Workbook
Name └_KAID_명의도용_방지서비스__Msafer: CSR!#REF!
Name 공통: CSR!$D$93:$D$112
Name 구분: #REF!
Name 기능고도화: #REF!
Name 마케팅: #REF!
Name 사업담당: #REF!
Name 서비스운영: CSR!$D$93:$D$112
Name 서비스품질관리: #REF!
Name 시스템운영: CSR!#REF!
Name 신규사업개발: #REF!
Name 신규서비스개발: CSR!#REF!
Name 인증플랫폼: CSR!#REF!
Name PASS기능개발: CSR!$D$68:$D$77
Name PASS활성화이벤트: CSR!$D$82:$D$89

Sheet CSR
E1: VarChar() | F1: Character | G1: =E&F | H1: 파트너 | L1: 사업계획 | M1: YYYY-MM | N1: 완료
E2: ABC_123 | F2: 012 | G2: =E2&"_"&F2 -> ABC_123_012 | H2: SI | L2: 신규 | N2: 진행중(개발착수 후~)
H3: ATON투자 | N3: 진행예정(협의개시~개발착수 전)
N4: 진행취소
B9: 사업추진과제 | H9: 업무요청 | L9: 처리일정 | O9: 인력투입(M/M) | AC9: 비고
B10: 구분 | C10: 중점추진과제 | D10: 상세추진과제 | E10: CSR_Level1 | F10: Level2 | G10: 업무아이디 | H10: R&R | I10: 요청일 | J10: 사업담당 | K10: 개발담당 | L10: 구분 | M10: 배포일정 | N10: 진행상태 | O10: 계획 | P10: 실적 | Q10: 25년 11월 | R10: 25년 12월 | S10: 26년 01월 | T10: 26년 02월 | U10: 26년 03월 | V10: 26년 04월 | W10: 26년 05월 | X10: 26년 06월 | Y10: 26년 07월 | Z10: 26년 08월 | AA10: 26년 09월 | AB10: 26년 10월
B11: 기능 고도화 | C11: PASS기능개발 | D11: PASS앱 광고영역 확대 및 고도화 (구글광고 연동 등) | E11: CSR_10100 | H11: 파트너 | J11: 이제훈C | K11: 백광규C | L11: 사업계획 | O11: 5 | P11: =SUM(Q11:AB11) -> 0.18421053 | Q11: =SUMIF('25년11월'!$F$1:$I$792,CSR!E11,'25년11월'!I:I) -> 0.13157895 | R11: =SUMIF('25년12월'!$F$1:$I$764,CSR!E11,'25년12월'!I:I) -> 0.052631579 | S11: =SUMIF('26년01월'!$F$1:$I$741,CSR!E11,'26년01월'!I:I) -> 0 | T11: =SUMIF('26년02월'!$F$1:$I$734,CSR!E11,'26년02월'!I:I) -> 0 | U11: =SUMIF('26년03월'!$F$1:$I$738,CSR!E11,'26년03월'!I:I) -> 0 | V11: =SUMIF('26년04월'!$F$1:$I$741,CSR!E11,'26년04월'!I:I) -> 0 | W11: =SUMIF('26년05월'!$F$1:$I$744,CSR!E11,'26년05월'!I:I) -> 0
D12: PASS 홈 화면 고도화 (쉬운 화면 적용 등) | E12: CSR_10200 | H12: 파트너 | J12: 박성훈C | K12: 백광규C | L12: 사업계획 | O12: 15 | P12: =SUM(Q12:AB12) -> 0.13157895 | Q12: =SUMIF('25년11월'!$F$1:$I$792,CSR!E12,'25년11월'!I:I) -> 0.052631579 | R12: =SUMIF('25년12월'!$F$1:$I$764,CSR!E12,'25년12월'!I:I) -> 0 | S12: =SUMIF('26년01월'!$F$1:$I$741,CSR!E12,'26년01월'!I:I) -> 0 | T12: =SUMIF('26년02월'!$F$1:$I$734,CSR!E12,'26년02월'!I:I) -> 0 | U12: =SUMIF('26년03월'!$F$1:$I$738,CSR!E12,'26년03월'!I:I) -> 0 | V12: =SUMIF('26년04월'!$F$1:$I$741,CSR!E12,'26년04월'!I:I) -> 0 | W12: =SUMIF('26년05월'!$F$1:$I$744,CSR!E12,'26년05월'!I:I) -> 0.078947368
D13: ㄴPASS MAIN 개편 | E13: CSR_10201 | H13: 파트너 | J13: 박성훈C | K13: 백광규C
D14: PASS 다크모드 지원 | E14: CSR_10300 | H14: 파트너 | J14: 박성훈C | K14: 백광규C | L14: 사업계획 | O14: 5 | P14: =SUM(Q14:AB14) -> 0.10526316 | Q14: =SUMIF('25년11월'!$F$1:$I$792,CSR!E14,'25년11월'!I:I) -> 0 | R14: =SUMIF('25년12월'!$F$1:$I$764,CSR!E14,'25년12월'!I:I) -> 0.10526316 | S14: =SUMIF('26년01월'!$F$1:$I$741,CSR!E14,'26년01월'!I:I) -> 0 | T14: =SUMIF('26년02월'!$F$1:$I$734,CSR!E14,'26년02월'!I:I) -> 0 | U14: =SUMIF('26년03월'!$F$1:$I$738,CSR!E14,'26년03월'!I:I) -> 0 | V14: =SUMIF('26년04월'!$F$1:$I$741,CSR!E14,'26년04월'!I:I) -> 0 | W14: =SUMIF('26년05월'!$F$1:$I$744,CSR!E14,'26년05월'!I:I) -> 0
D15: PASS MY 화면 고도화 | E15: CSR_10400 | H15: 파트너 | J15: 박성훈C | K15: 백광규C | L15: 사업계획 | M15: 26년 3월 | N15: 진행중 | O15: 10 | P15: =SUM(Q15:AB15) -> 11.773684 | Q15: =SUMIF('25년11월'!$F$1:$I$792,CSR!E15,'25년11월'!I:I) -> 0.5 | R15: =SUMIF('25년12월'!$F$1:$I$764,CSR!E15,'25년12월'!I:I) -> 3.3157895 | S15: =SUMIF('26년01월'!$F$1:$I$741,CSR!E15,'26년01월'!I:I) -> 3.3947368 | T15: =SUMIF('26년02월'!$F$1:$I$734,CSR!E15,'26년02월'!I:I) -> 0.78947368 | U15: =SUMIF('26년03월'!$F$1:$I$738,CSR!E15,'26년03월'!I:I) -> 1.2368421 | V15: =SUMIF('26년04월'!$F$1:$I$741,CSR!E15,'26년04월'!I:I) -> 1.9736842 | W15: =SUMIF('26년05월'!$F$1:$I$744,CSR!E15,'26년05월'!I:I) -> 0.56315789
D16: PASS 전체 화면 고도화 | E16: CSR_10500 | H16: 파트너 | J16: 박성훈C | K16: 백광규C | L16: 사업계획 | O16: 5 | P16: =SUM(Q16:AB16) -> 0 | Q16: =SUMIF('25년11월'!$F$1:$I$792,CSR!E16,'25년11월'!I:I) -> 0 | R16: =SUMIF('25년12월'!$F$1:$I$764,CSR!E16,'25년12월'!I:I) -> 0 | S16: =SUMIF('26년01월'!$F$1:$I$741,CSR!E16,'26년01월'!I:I) -> 0 | T16: =SUMIF('26년02월'!$F$1:$I$734,CSR!E16,'26년02월'!I:I) -> 0 | U16: =SUMIF('26년03월'!$F$1:$I$738,CSR!E16,'26년03월'!I:I) -> 0 | V16: =SUMIF('26년04월'!$F$1:$I$741,CSR!E16,'26년04월'!I:I) -> 0 | W16: =SUMIF('26년05월'!$F$1:$I$744,CSR!E16,'26년05월'!I:I) -> 0
D17: PASS 알림내역 화면 고도화 | E17: CSR_10600 | H17: 파트너 | J17: 박성훈C | K17: 백광규C | L17: 사업계획 | O17: 5 | P17: =SUM(Q17:AB17) -> 0.26315789 | Q17: =SUMIF('25년11월'!$F$1:$I$792,CSR!E17,'25년11월'!I:I) -> 0.26315789 | R17: =SUMIF('25년12월'!$F$1:$I$764,CSR!E17,'25년12월'!I:I) -> 0 | S17: =SUMIF('26년01월'!$F$1:$I$741,CSR!E17,'26년01월'!I:I) -> 0 | T17: =SUMIF('26년02월'!$F$1:$I$734,CSR!E17,'26년02월'!I:I) -> 0 | U17: =SUMIF('26년03월'!$F$1:$I$738,CSR!E17,'26년03월'!I:I) -> 0 | V17: =SUMIF('26년04월'!$F$1:$I$741,CSR!E17,'26년04월'!I:I) -> 0 | W17: =SUMIF('26년05월'!$F$1:$I$744,CSR!E17,'26년05월'!I:I) -> 0
D18: PASS 앱인앱 고도화 (웹뷰 고도화) | E18: CSR_10700 | H18: 파트너 | J18: 박성훈C | K18: 백광규C | L18: 사업계획 | N18: 진행중 | O18: 5 | P18: =SUM(Q18:AB18) -> 1 | Q18: =SUMIF('25년11월'!$F$1:$I$792,CSR!E18,'25년11월'!I:I) -> 0 | R18: =SUMIF('25년12월'!$F$1:$I$764,CSR!E18,'25년12월'!I:I) -> 0.5 | S18: =SUMIF('26년01월'!$F$1:$I$741,CSR!E18,'26년01월'!I:I) -> 0 | T18: =SUMIF('26년02월'!$F$1:$I$734,CSR!E18,'26년02월'!I:I) -> 0 | U18: =SUMIF('26년03월'!$F$1:$I$738,CSR!E18,'26년03월'!I:I) -> 0.31578947 | V18: =SUMIF('26년04월'!$F$1:$I$741,CSR!E18,'26년04월'!I:I) -> 0.15789474 | W18: =SUMIF('26년05월'!$F$1:$I$744,CSR!E18,'26년05월'!I:I) -> 0.026315789
D19: PASS 주소록 기능 개발 | E19: CSR_10800 | H19: 파트너 | J19: 박성훈C | K19: 백광규C | L19: 사업계획 | N19: 진행중 | O19: 5 | P19: =SUM(Q19:AB19) -> 7.7894737 | Q19: =SUMIF('25년11월'!$F$1:$I$792,CSR!E19,'25년11월'!I:I) -> 0 | R19: =SUMIF('25년12월'!$F$1:$I$764,CSR!E19,'25년12월'!I:I) -> 0 | S19: =SUMIF('26년01월'!$F$1:$I$741,CSR!E19,'26년01월'!I:I) -> 1.7894737 | T19: =SUMIF('26년02월'!$F$1:$I$734,CSR!E19,'26년02월'!I:I) -> 2.5 | U19: =SUMIF('26년03월'!$F$1:$I$738,CSR!E19,'26년03월'!I:I) -> 0.73684211 | V19: =SUMIF('26년04월'!$F$1:$I$741,CSR!E19,'26년04월'!I:I) -> 1.7105263 | W19: =SUMIF('26년05월'!$F$1:$I$744,CSR!E19,'26년05월'!I:I) -> 1.0526316
D20: PASS 운영/마케팅 기능 개선 | E20: CSR_10900 | H20: 파트너 | J20: 이제훈C | K20: 백광규C | L20: 사업계획 | O20: 8 | P20: =SUM(Q20:AB20) -> 0 | Q20: =SUMIF('25년11월'!$F$1:$I$792,CSR!E20,'25년11월'!I:I) -> 0 | R20: =SUMIF('25년12월'!$F$1:$I$764,CSR!E20,'25년12월'!I:I) -> 0 | S20: =SUMIF('26년01월'!$F$1:$I$741,CSR!E20,'26년01월'!I:I) -> 0 | T20: =SUMIF('26년02월'!$F$1:$I$734,CSR!E20,'26년02월'!I:I) -> 0 | U20: =SUMIF('26년03월'!$F$1:$I$738,CSR!E20,'26년03월'!I:I) -> 0 | V20: =SUMIF('26년04월'!$F$1:$I$741,CSR!E20,'26년04월'!I:I) -> 0 | W20: =SUMIF('26년05월'!$F$1:$I$744,CSR!E20,'26년05월'!I:I) -> 0
D21: PASS 로그인 방식 개선 (정책 강화 등) | E21: CSR_11000 | H21: 파트너 | J21: 박성훈C | K21: 백광규C | L21: 사업계획 | N21: 진행중 | O21: 5 | P21: =SUM(Q21:AB21) -> 0.42105263 | Q21: =SUMIF('25년11월'!$F$1:$I$792,CSR!E21,'25년11월'!I:I) -> 0 | R21: =SUMIF('25년12월'!$F$1:$I$764,CSR!E21,'25년12월'!I:I) -> 0 | S21: =SUMIF('26년01월'!$F$1:$I$741,CSR!E21,'26년01월'!I:I) -> 0 | T21: =SUMIF('26년02월'!$F$1:$I$734,CSR!E21,'26년02월'!I:I) -> 0.15789474 | U21: =SUMIF('26년03월'!$F$1:$I$738,CSR!E21,'26년03월'!I:I) -> 0.078947368 | V21: =SUMIF('26년04월'!$F$1:$I$741,CSR!E21,'26년04월'!I:I) -> 0.078947368 | W21: =SUMIF('26년05월'!$F$1:$I$744,CSR!E21,'26년05월'!I:I) -> 0.10526316
D22: ㄴ PIN 인증방식 전환 | E22: CSR_11001 | H22: 파트너 | J22: 박성훈C | K22: 백광규C | N22: 진행중 | P22: =SUM(Q22:AB22) -> 0 | U22: =SUMIF('26년03월'!$F$1:$I$738,CSR!E22,'26년03월'!I:I) -> 0 | V22: =SUMIF('26년04월'!$F$1:$I$741,CSR!E22,'26년04월'!I:I) -> 0 | W22: =SUMIF('26년05월'!$F$1:$I$744,CSR!E22,'26년05월'!I:I) -> 0
D23: ㄴ JWT 도입에 따른 앱 진입/인증 흐름 개선 | E23: CSR_11002 | H23: 파트너 | J23: 박성훈C | K23: 백광규C | N23: 진행중 | P23: =SUM(Q23:AB23) -> 0.57894737 | U23: =SUMIF('26년03월'!$F$1:$I$738,CSR!E23,'26년03월'!I:I) -> 0.57894737 | V23: =SUMIF('26년04월'!$F$1:$I$741,CSR!E23,'26년04월'!I:I) -> 0 | W23: =SUMIF('26년05월'!$F$1:$I$744,CSR!E23,'26년05월'!I:I) -> 0
D24: PASS 공통 화면 개선 (모달형태 약관 화면 적용, 알림팝업 적용 등) | E24: CSR_11100 | H24: 파트너 | J24: 박성훈C | K24: 백광규C | L24: 사업계획 | N24: 진행중 | O24: 5 | P24: =SUM(Q24:AB24) -> 1.5263158 | Q24: =SUMIF('25년11월'!$F$1:$I$792,CSR!E24,'25년11월'!I:I) -> 0.026315789 | R24: =SUMIF('25년12월'!$F$1:$I$764,CSR!E24,'25년12월'!I:I) -> 0.10526316 | S24: =SUMIF('26년01월'!$F$1:$I$741,CSR!E24,'26년01월'!I:I) -> 0.26315789 | T24: =SUMIF('26년02월'!$F$1:$I$734,CSR!E24,'26년02월'!I:I) -> 0.36842105 | U24: =SUMIF('26년03월'!$F$1:$I$738,CSR!E24,'26년03월'!I:I) -> 0.39473684 | V24: =SUMIF('26년04월'!$F$1:$I$741,CSR!E24,'26년04월'!I:I) -> 0.18421053 | W24: =SUMIF('26년05월'!$F$1:$I$744,CSR!E24,'26년05월'!I:I) -> 0.18421053
D25: PASS 홈페이지 고도화 | E25: CSR_11200 | H25: 파트너 | J25: 박성훈C | K25: 백광규C | L25: 사업계획 | N25: 진행중 | O25: 2 | P25: =SUM(Q25:AB25) -> 0 | Q25: =SUMIF('25년11월'!$F$1:$I$792,CSR!E25,'25년11월'!I:I) -> 0 | R25: =SUMIF('25년12월'!$F$1:$I$764,CSR!E25,'25년12월'!I:I) -> 0 | S25: =SUMIF('26년01월'!$F$1:$I$741,CSR!E25,'26년01월'!I:I) -> 0 | T25: =SUMIF('26년02월'!$F$1:$I$734,CSR!E25,'26년02월'!I:I) -> 0 | U25: =SUMIF('26년03월'!$F$1:$I$738,CSR!E25,'26년03월'!I:I) -> 0 | V25: =SUMIF('26년04월'!$F$1:$I$741,CSR!E25,'26년04월'!I:I) -> 0 | W25: =SUMIF('26년05월'!$F$1:$I$744,CSR!E25,'26년05월'!I:I) -> 0
D26: 서비스 개발 | E26: CSR_11300 | H26: 파트너 | J26: 박성훈C | K26: 백광규C | L26: 사업계획 | N26: 진행중 | O26: 10 | P26: =SUM(Q26:AB26) -> 21.078947 | Q26: =SUMIF('25년11월'!$F$1:$I$792,CSR!E26,'25년11월'!I:I) -> 1.3684211 | R26: =SUMIF('25년12월'!$F$1:$I$764,CSR!E26,'25년12월'!I:I) -> 2.3421053 | S26: =SUMIF('26년01월'!$F$1:$I$741,CSR!E26,'26년01월'!I:I) -> 2 | T26: =SUMIF('26년02월'!$F$1:$I$734,CSR!E26,'26년02월'!I:I) -> 0.52631579 | U26: =SUMIF('26년03월'!$F$1:$I$738,CSR!E26,'26년03월'!I:I) -> 1.7894737 | V26: =SUMIF('26년04월'!$F$1:$I$741,CSR!E26,'26년04월'!I:I) -> 8.1052632 | W26: =SUMIF('26년05월'!$F$1:$I$744,CSR!E26,'26년05월'!I:I) -> 4.9473684
D27: ㄴ회원가입화면 개선 | E27: CSR_11301 | H27: 파트너 | J27: 박성훈C | K27: 백광규C | M27: 25년 12월 | N27: 완료 | P27: =SUM(Q27:AB27) -> 0.28947368 | Q27: =SUMIF('25년11월'!$F$1:$I$792,CSR!E27,'25년11월'!I:I) -> 0.26315789 | R27: =SUMIF('25년12월'!$F$1:$I$764,CSR!E27,'25년12월'!I:I) -> 0.026315789 | S27: =SUMIF('26년01월'!$F$1:$I$741,CSR!E27,'26년01월'!I:I) -> 0 | T27: =SUMIF('26년02월'!$F$1:$I$734,CSR!E27,'26년02월'!I:I) -> 0 | U27: =SUMIF('26년03월'!$F$1:$I$738,CSR!E27,'26년03월'!I:I) -> 0 | V27: =SUMIF('26년04월'!$F$1:$I$741,CSR!E27,'26년04월'!I:I) -> 0 | W27: =SUMIF('26년05월'!$F$1:$I$744,CSR!E27,'26년05월'!I:I) -> 0
D28: ㄴ펫신분증 UI 개선 | E28: CSR_11302 | H28: 파트너 | J28: 박성훈C | K28: 백광규C | M28: 25년 12월 | N28: 완료 | P28: =SUM(Q28:AB28) -> 1.5789474 | Q28: =SUMIF('25년11월'!$F$1:$I$792,CSR!E28,'25년11월'!I:I) -> 0.31578947 | R28: =SUMIF('25년12월'!$F$1:$I$764,CSR!E28,'25년12월'!I:I) -> 0.15789474 | S28: =SUMIF('26년01월'!$F$1:$I$741,CSR!E28,'26년01월'!I:I) -> 0.84210526 | T28: =SUMIF('26년02월'!$F$1:$I$734,CSR!E28,'26년02월'!I:I) -> 0.26315789 | U28: =SUMIF('26년03월'!$F$1:$I$738,CSR!E28,'26년03월'!I:I) -> 0 | V28: =SUMIF('26년04월'!$F$1:$I$741,CSR!E28,'26년04월'!I:I) -> 0 | W28: =SUMIF('26년05월'!$F$1:$I$744,CSR!E28,'26년05월'!I:I) -> 0
D29: ㄴ계좌인증 금융기관 선택 화면 현행화 | E29: CSR_11303 | H29: 파트너 | J29: 박성훈C | K29: 백광규C | M29: 26년 03월 | N29: 완료 | P29: =SUM(Q29:AB29) -> 1.0157895 | Q29: =SUMIF('25년11월'!$F$1:$I$792,CSR!E29,'25년11월'!I:I) -> 0 | R29: =SUMIF('25년12월'!$F$1:$I$764,CSR!E29,'25년12월'!I:I) -> 0.57894737 | S29: =SUMIF('26년01월'!$F$1:$I$741,CSR!E29,'26년01월'!I:I) -> 0 | T29: =SUMIF('26년02월'!$F$1:$I$734,CSR!E29,'26년02월'!I:I) -> 0.026315789 | U29: =SUMIF('26년03월'!$F$1:$I$738,CSR!E29,'26년03월'!I:I) -> 0.27894737 | V29: =SUMIF('26년04월'!$F$1:$I$741,CSR!E29,'26년04월'!I:I) -> 0.042105263 | W29: =SUMIF('26년05월'!$F$1:$I$744,CSR!E29,'26년05월'!I:I) -> 0.089473684
D30: ㄴ1:1 문의 카테고리 추가 | E30: CSR_11304 | H30: 파트너 | J30: 박성훈C | K30: 백광규C | M30: 26년 03월 | N30: 완료 | P30: =SUM(Q30:AB30) -> 0.42105263 | Q30: =SUMIF('25년11월'!$F$1:$I$792,CSR!E30,'25년11월'!I:I) -> 0 | R30: =SUMIF('25년12월'!$F$1:$I$764,CSR!E30,'25년12월'!I:I) -> 0.15789474 | S30: =SUMIF('26년01월'!$F$1:$I$741,CSR!E30,'26년01월'!I:I) -> 0.10526316 | T30: =SUMIF('26년02월'!$F$1:$I$734,CSR!E30,'26년02월'!I:I) -> 0.15789474 | U30: =SUMIF('26년03월'!$F$1:$I$738,CSR!E30,'26년03월'!I:I) -> 0 | V30: =SUMIF('26년04월'!$F$1:$I$741,CSR!E30,'26년04월'!I:I) -> 0 | W30: =SUMIF('26년05월'!$F$1:$I$744,CSR!E30,'26년05월'!I:I) -> 0
D31: ㄴ유·무료 서비스 동의화면 개선 | E31: CSR_11305 | H31: 파트너 | J31: 박성훈C | K31: 백광규C | M31: 26년 06월 | N31: 진행중 | P31: =SUM(Q31:AB31) -> 1.3684211 | Q31: =SUMIF('25년11월'!$F$1:$I$792,CSR!E31,'25년11월'!I:I) -> 0 | R31: =SUMIF('25년12월'!$F$1:$I$764,CSR!E31,'25년12월'!I:I) -> 0.42105263 | S31: =SUMIF('26년01월'!$F$1:$I$741,CSR!E31,'26년01월'!I:I) -> 0.52631579 | T31: =SUMIF('26년02월'!$F$1:$I$734,CSR!E31,'26년02월'!I:I) -> 0 | U31: =SUMIF('26년03월'!$F$1:$I$738,CSR!E31,'26년03월'!I:I) -> 0 | V31: =SUMIF('26년04월'!$F$1:$I$741,CSR!E31,'26년04월'!I:I) -> 0.42105263 | W31: =SUMIF('26년05월'!$F$1:$I$744,CSR!E31,'26년05월'!I:I) -> 0
D32: ㄴ하단GNB 개편 | E32: CSR_11306 | H32: 파트너 | J32: 박성훈C | K32: 백광규C | M32: 26년 03월 | N32: 완료 | P32: =SUM(Q32:AB32) -> 0.86842105 | Q32: =SUMIF('25년11월'!$F$1:$I$792,CSR!E32,'25년11월'!I:I) -> 0 | R32: =SUMIF('25년12월'!$F$1:$I$764,CSR!E32,'25년12월'!I:I) -> 0.26315789 | S32: =SUMIF('26년01월'!$F$1:$I$741,CSR!E32,'26년01월'!I:I) -> 0.55263158 | T32: =SUMIF('26년02월'!$F$1:$I$734,CSR!E32,'26년02월'!I:I) -> 0 | U32: =SUMIF('26년03월'!$F$1:$I$738,CSR!E32,'26년03월'!I:I) -> 0.052631579 | V32: =SUMIF('26년04월'!$F$1:$I$741,CSR!E32,'26년04월'!I:I) -> 0 | W32: =SUMIF('26년05월'!$F$1:$I$744,CSR!E32,'26년05월'!I:I) -> 0
D33: ㄴ부가서비스 다회선 전환시 안내 문구 및 마스킹 처리 적용 | E33: CSR_11307 | H33: 파트너 | J33: 이제훈C | K33: 백광규C | M33: 26년 03월 | N33: 완료 | P33: =SUM(Q33:AB33) -> 0.31578947 | Q33: =SUMIF('25년11월'!$F$1:$I$792,CSR!E33,'25년11월'!I:I) -> 0 | R33: =SUMIF('25년12월'!$F$1:$I$764,CSR!E33,'25년12월'!I:I) -> 0 | S33: =SUMIF('26년01월'!$F$1:$I$741,CSR!E33,'26년01월'!I:I) -> 0.31578947 | T33: =SUMIF('26년02월'!$F$1:$I$734,CSR!E33,'26년02월'!I:I) -> 0 | U33: =SUMIF('26년03월'!$F$1:$I$738,CSR!E33,'26년03월'!I:I) -> 0 | V33: =SUMIF('26년04월'!$F$1:$I$741,CSR!E33,'26년04월'!I:I) -> 0 | W33: =SUMIF('26년05월'!$F$1:$I$744,CSR!E33,'26년05월'!I:I) -> 0
D34: ㄴ폴라리스오피스 기본앱 설정 관련 수정 | E34: CSR_11308 | H34: 파트너 | J34: 이제훈C | K34: 백광규C | M34: 26년 06월 | N34: 진행중 | P34: =SUM(Q34:AB34) -> 0 | T34: =SUMIF('26년02월'!$F$1:$I$734,CSR!E34,'26년02월'!I:I) -> 0 | U34: =SUMIF('26년03월'!$F$1:$I$738,CSR!E34,'26년03월'!I:I) -> 0 | V34: =SUMIF('26년04월'!$F$1:$I$741,CSR!E34,'26년04월'!I:I) -> 0 | W34: =SUMIF('26년05월'!$F$1:$I$744,CSR!E34,'26년05월'!I:I) -> 0
D35: ㄴ고객의 소리 링크 변경 | E35: CSR_11309 | H35: 파트너 | J35: 이제훈C | K35: 백광규C | M35: 26년 06월 | N35: 진행중 | P35: =SUM(Q35:AB35) -> 0.47368421 | T35: =SUMIF('26년02월'!$F$1:$I$734,CSR!E35,'26년02월'!I:I) -> 0.26315789 | U35: =SUMIF('26년03월'!$F$1:$I$738,CSR!E35,'26년03월'!I:I) -> 0.21052632 | V35: =SUMIF('26년04월'!$F$1:$I$741,CSR!E35,'26년04월'!I:I) -> 0 | W35: =SUMIF('26년05월'!$F$1:$I$744,CSR!E35,'26년05월'!I:I) -> 0
D36: ㄴMIS 실행 시 선택 업데이트 기능 추가 | E36: CSR_11310 | H36: 파트너 | J36: 박병주C | K36: 백광규C | M36: 26년 06월 | N36: 진행중 | P36: =SUM(Q36:AB36) -> 0.36842105 | U36: =SUMIF('26년03월'!$F$1:$I$738,CSR!E36,'26년03월'!I:I) -> 0.36842105 | V36: =SUMIF('26년04월'!$F$1:$I$741,CSR!E36,'26년04월'!I:I) -> 0 | W36: =SUMIF('26년05월'!$F$1:$I$744,CSR!E36,'26년05월'!I:I) -> 0
D37: ㄴ애드몹 광고형식 추가 | E37: CSR_11311 | H37: 파트너 | J37: 박성훈C | K37: 백광규C | M37: 26년 06월 | N37: 진행중 | P37: =SUM(Q37:AB37) -> 0.010526316 | U37: =SUMIF('26년03월'!$F$1:$I$738,CSR!E37,'26년03월'!I:I) -> 0.010526316 | V37: =SUMIF('26년04월'!$F$1:$I$741,CSR!E37,'26년04월'!I:I) -> 0 | W37: =SUMIF('26년05월'!$F$1:$I$744,CSR!E37,'26년05월'!I:I) -> 0
D38: ㄴ PASS 전자고지 열람 시 IMEI 조회 실패 오류 안내 개선 | E38: CSR_11312 | H38: 파트너 | J38: 박성훈C | K38: 백광규C | M38: 26년 04월 | N38: 완료 | P38: =SUM(Q38:AB38) -> 0.57894737 | U38: =SUMIF('26년03월'!$F$1:$I$738,CSR!E38,'26년03월'!I:I) -> 0.57894737 | V38: =SUMIF('26년04월'!$F$1:$I$741,CSR!E38,'26년04월'!I:I) -> 0 | W38: =SUMIF('26년05월'!$F$1:$I$744,CSR!E38,'26년05월'!I:I) -> 0
D39: ㄴIOS : PASS 앱 icloud (클라우드 복원시 재가입 프로세스 유도) | E39: CSR_11313 | H39: 파트너 | J39: 박성훈C | K39: 백광규C | M39: 26년 04월 | N39: 완료 | P39: =SUM(Q39:AB39) -> 0.15789474 | U39: =SUMIF('26년03월'!$F$1:$I$738,CSR!E39,'26년03월'!I:I) -> 0.15789474 | V39: =SUMIF('26년04월'!$F$1:$I$741,CSR!E39,'26년04월'!I:I) -> 0 | W39: =SUMIF('26년05월'!$F$1:$I$744,CSR!E39,'26년05월'!I:I) -> 0
D40: ㄴ외부플랫폼 진입 시 브릿지 페이지 | E40: CSR_11314 | H40: 파트너 | J40: 박성훈C | K40: 백광규C | M40: 26년 06월 | N40: 진행중 | P40: =SUM(Q40:AB40) -> 1.2105263 | V40: =SUMIF('26년04월'!$F$1:$I$741,CSR!E40,'26년04월'!I:I) -> 0.57894737 | W40: =SUMIF('26년05월'!$F$1:$I$744,CSR!E40,'26년05월'!I:I) -> 0.63157895
D41: ㄴ업데이트 후 서비스 진입 개선 | E41: CSR_11315 | H41: 파트너 | J41: 박성훈C | K41: 백광규C | M41: 26년 06월 | N41: 진행중 | P41: =SUM(Q41:AB41) -> 0.52631579 | V41: =SUMIF('26년04월'!$F$1:$I$741,CSR!E41,'26년04월'!I:I) -> 0.52631579 | W41: =SUMIF('26년05월'!$F$1:$I$744,CSR!E41,'26년05월'!I:I) -> 0
D42: ㄴ유료가입 페이지 바텀시트 처리 | E42: CSR_11316 | H42: 파트너 | J42: 박병주C | K42: 백광규C | M42: 26년 08월 | N42: 진행중 | P42: =SUM(Q42:AB42) -> 0.26315789 | W42: =SUMIF('26년05월'!$F$1:$I$744,CSR!E42,'26년05월'!I:I) -> 0.26315789
D43: ㄴPASS 내 스와이프로 뒤로가기 | E43: CSR_11317 | H43: 파트너 | J43: 박병주C | K43: 백광규C | M43: 26년 08월 | N43: 진행중 | P43: =SUM(Q43:AB43) -> 0.15789474 | W43: =SUMIF('26년05월'!$F$1:$I$744,CSR!E43,'26년05월'!I:I) -> 0.15789474
D44: ㄴ외국인 해외 송금 | E44: CSR_11317 | H44: 파트너 | J44: 박성훈C | K44: 백광규C | M44: 26년 10월 | N44: 진행중 | P44: =SUM(Q44:AB44) -> 0
...

Sheet 26년06월
A1: 월 | B1: 구분 | C1: 중점추진과제 | D1: 상세추진과제 | E1: 상세 추진 내용 | F1: CSR ID | G1: 완료일시 | H1: 투입M/D | I1: 투입M/M | J1: 처리자 | K1: 비고 | L1: AI활용 | M1: AI활용내용
A2: 5월 | B2: 서비스 품질관리 | C2: 서비스 운영 | D2: 업무보고 및 협의 | E2: PASS전략파트너 개발 관련 업무보고 및 협의 - 내부/외부 회의 및 협의 | F2: =VLOOKUP(D2,CSR!$D$4:$E$1180,2,FALSE) -> CSR_30600 | G2: 46171 | H2: 5 | I2: =H2*10/190 -> 0.26315789 | J2: 개발PM | L2: 하 | M2: 실제 협의는 이해관계 조율, 내부 판단, 대외 커뮤니케이션이 핵심이므로 AI 활용 효과가 제한적. 활용 방안 추가 모색
A3: 6월 | B3: 서비스 품질관리 | C3: 서비스 운영 | D3: 업무보고 및 협의 | E3: PASS전략파트너 개발 관련 업무보고 및 협의 - 내부/외부 회의 및 협의 | F3: =VLOOKUP(D3,CSR!$D$4:$E$1180,2,FALSE) -> CSR_30600 | G3: 46178 | H3: 5 | I3: =H3*10/190 -> 0.26315789 | J3: 개발PM | L3: 하 | M3: 실제 협의는 이해관계 조율, 내부 판단, 대외 커뮤니케이션이 핵심이므로 AI 활용 효과가 제한적. 활용 방안 추가 모색
A4: 6월 | B4: 서비스 품질관리 | C4: 서비스 운영 | D4: 업무보고 및 협의 | E4: PASS전략파트너 개발 관련 업무보고 및 협의 - 내부/외부 회의 및 협의 | F4: =VLOOKUP(D4,CSR!$D$4:$E$1180,2,FALSE) -> CSR_30600 | G4: 46185 | H4: 5 | I4: =H4*10/190 -> 0.26315789 | J4: 개발PM | L4: 하 | M4: 실제 협의는 이해관계 조율, 내부 판단, 대외 커뮤니케이션이 핵심이므로 AI 활용 효과가 제한적. 활용 방안 추가 모색
A5: 6월 | B5: 서비스 품질관리 | C5: 서비스 운영 | D5: 업무보고 및 협의 | E5: PASS전략파트너 개발 관련 업무보고 및 협의 - 내부/외부 회의 및 협의 | F5: =VLOOKUP(D5,CSR!$D$4:$E$1180,2,FALSE) -> CSR_30600 | G5: 46192 | H5: 4 | I5: =H5*10/190 -> 0.21052632 | J5: 개발PM | L5: 하 | M5: 실제 협의는 이해관계 조율, 내부 판단, 대외 커뮤니케이션이 핵심이므로 AI 활용 효과가 제한적. 활용 방안 추가 모색
A6: 5월 | B6: 기능 고도화 | C6: PASS기능개발 | D6: PASS UI/UX 개선 | E6: 인증내역 조회기간 선택 시트, 월 선택 영역, 모바일신분증 인증 유형 아이콘 AOS 기능 개발 | F6: =VLOOKUP(D6,CSR!$D$4:$E$1180,2,FALSE) -> CSR_11500 | G6: 46171 | H6: 1 | I6: =H6*10/190 -> 0.052631579 | J6: Android개발자2 | L6: 상 | M6: 인증내역 월조회 UI 상태 처리와 유형 아이콘 매핑 코드 자동 생성하여 화면 구현 누락 방지
A7: 5월 | B7: 기능 고도화 | C7: PASS기능개발 | D7: OS 보안 대응 | E7: 안드로이드 16 대응 범위 확인 및 AOS 호환 기능 개발 | F7: =VLOOKUP(D7,CSR!$D$4:$E$1180,2,FALSE) -> CSR_11501 | G7: 46171 | H7: 1 | I7: =H7*10/190 -> 0.052631579 | J7: Android개발자2 | L7: 상 | M7: Android 16 권한/백그라운드 영향도 사전 검토와 대응 코드 패턴 생성으로 OS 변경 사이드 이슈 사전 확인
A8: 5월 | B8: 기능 고도화 | C8: PASS기능개발 | D8: PASS MY 화면 고도화 | E8: MY화면 CP 연동 영역 업데이트 안내 추가 AOS 기능 개발 | F8: =VLOOKUP(D8,CSR!$D$4:$E$1180,2,FALSE) -> CSR_10400 | G8: 46171 | H8: 1 | I8: =H8*10/190 -> 0.052631579 | J8: Android개발자2 | L8: 상 | M8: MY화면 CP 연동 응답 바인딩과 업데이트 안내 UI 코드 자동 생성하여 API 연동 영향 범위 명확화
A9: 5월 | B9: 기능 고도화 | C9: PASS기능개발 | D9: ㄴ26년 6월 앱 배포 검수 | E9: 6월 앱 CVT 국내스탁 가입배너 및 안심클라우드 업로드 크래시 확인 대응 | F9: =VLOOKUP(D9,CSR!$D$4:$E$1180,2,FALSE) -> CSR_11416 | G9: 46171 | H9: 1 | I9: =H9*10/190 -> 0.052631579 | J9: Android개발자2 | L9: 하 | M9: CVT 재현 케이스와 회귀 테스트 체크리스트 자동 생성하여 검수 항목 누락 방지
A10: 5월 | B10: 기능 고도화 | C10: PASS기능개발 | D10: ㄴ26년 5월 2차 서버 검수 | E10: 부가서비스/관리자/일반서비스 5월 2차 서버 반영 전후 확인 및 형상 병합·태깅 지원 | F10: =VLOOKUP(D10,CSR!$D$4:$E$1180,2,FALSE) -> CSR_11415 | G10: 46171 | H10: 2 | I10: =H10*10/190 -> 0.10526316 | J10: 서버개발자5 | L10: 하 | M10: 서버 반영 순서 체크리스트와 형상 병합 확인 목록 자동 생성하여 반영 순서 오류 방지
A11: 5월 | B11: 기능 고도화 | C11: PASS기능개발 | D11: 서비스 개발 | E11: 1:1문의하기 분리보관 스케줄러 GC Full 조치 및 부가서비스 유료가입창 관리자 수정 개발 | F11: =VLOOKUP(D11,CSR!$D$4:$E$1180,2,FALSE) -> CSR_11300 | G11: 46171 | H11: 1 | I11: =H11*10/190 -> 0.052631579 | J11: 서버개발자5 | L11: 상 | M11: 스케줄러 GC Full 원인 후보 분석과 관리자 화면 수정 코드 자동 생성으로 동일 유형 오류 재발 가능성 감소
A12: 5월 | B12: 마케팅 | C12: PASS활성화 이벤트 | D12: ㄴ주소록 오픈 이벤트 (with 오피스도우미) | E12: 26년 4월 주소록X오피스도우미 주별 응모자 데이터 및 PUSH 통계 추출 요청 대응 | F12: =VLOOKUP(D12,CSR!$D$4:$E$1180,2,FALSE) -> CSR_20006 | G12: 46171 | H12: 1 | I12: =H12*10/190 -> 0.052631579 | J12: 서버개발자5 | L12: 중 | M12: 응모자 추출 SQL과 PUSH 통계 검증 쿼리 자동 생성하여 조건 누락 및 집계 오류 감소
A13: 5월 | B13: 기능 고도화 | C13: PASS기능개발 | D13: ㄴ26년 5월 2차 서버 검수 | E13: 모바일신분증 DVT 산출물, 통합인증 IMEI 제거 검수 테스트 및 암호화 필드 조회 확인 | F13: =VLOOKUP(D13,CSR!$D$4:$E$1180,2,FALSE) -> CSR_11415 | G13: 46171 | H13: 2 | I13: =H13*10/190 -> 0.10526316 | J13: 서버개발자4 | L13: 중 | M13: DVT 산출물 초안과 IMEI 제거 검증 쿼리 자동 생성하여 검수 항목 누락 방지
... A169: 6월 | B169: 기능 고도화 | C169: PASS기능개발 | D169: ㄴPASS 내 스와이프로 뒤로가기 | E169: 스와이프 뒤로가기 제스처 도입 - 기획서 수정, 개발 협의 및 문의 대응 - 타 서비스 및 현 버전의 앱 동작 테스트 | F169: =VLOOKUP(D169,CSR!$D$4:$E$1180,2,FALSE) -> CSR_11317 | G169: 46192 | H169: 3 | I169: =H169*10/190 -> 0.15789474 | J169: 기획자1 | L169: 중 | M169: OS 별 최신 시스템 제스처 가이드라인 이슈 분석 및 기존 서비스 인터랙션과의 충돌 범위 사전 검토 시 활용함
A170: 6월 | B170: 기능 고도화 | C170: PASS기능개발 | D170: ㄴ26년 6월 앱 배포 검수 | E170: 6월 앱업데이트 - 서버 상용 반영 모니터링 및 관리자 데이터 세팅 - CVT 대응 | F170: =VLOOKUP(D170,CSR!$D$4:$E$1180,2,FALSE) -> CSR_11416 | G170: 46192 | H170: 1 | I170: =H170*10/190 -> 0.052631579 | J170: 기획자1
A171: 6월 | B171: 신규사업 개발 | C171: 인증플랫폼 | D171: 인증서 고도화 | E171: PASS인증서 생체인증 도입 - 기획서 수정, 개발 협의 및 문의 대응 | F171: =VLOOKUP(D171,CSR!$D$4:$E$1180,2,FALSE) -> CSR_40500 | G171: 46192 | H171: 2 | I171: =H171*10/190 -> 0.10526316 | J171: 기획자1 | L171: 중 | M171: 생체인증 실패 시 대체 인증 수단 전환 설계를 위한 다양한 예외 케이스 설계 및 구체화 시 활용함
A172: 6월 | B172: 신규사업 개발 | C172: 인증플랫폼 | D172: 휴대폰결제 고도화 | E172: 휴대폰결제 고도화 (결제비밀번호 도입, 인증수단 다각화, 바코드 바로가기 기능 추가) - 휴대폰결제 개발 및 간편본인확인 서버 측과 연동 관련 협의 - 기획서 작성 및 수정, 내부 개발 협의 및 문의 대응 | F172: =VLOOKUP(D172,CSR!$D$4:$E$1180,2,FALSE) -> CSR_40700 | G172: 46192 | H172: 4 | I172: =H172*10/190 -> 0.21052632 | J172: 기획자1 | L172: 중 | M172: 서버 연동 구조와 하위 호환성 리스크 파악, 개발 담당자 피드백의 기술적 개념과 통신 구조를 해석하는데 활용함
A173: 6월 | B173: 신규사업 개발 | C173: 인증플랫폼 | D173: 통신업무 "안면인증" PASS 활용 기능 및 사업화 | E173: 안면인증 통계 고도화 - 요구사항 분석, 기획서 작성, 개발 협의 및 문의 대응 | F173: =VLOOKUP(D173,CSR!$D$4:$E$1180,2,FALSE) -> CSR_40400 | G173: 46192 | H173: 2 | I173: =H173*10/190 -> 0.10526316 | J173: 기획자1 | L173: 중 | M173: 지표 설계 및 기획서 초안 작성 시 활용함
A174: 6월 | B174: 신규사업 개발 | C174: 인증플랫폼 | D174: 모바일신분증 고도화 (라인업 확대_시민증 관광증) | E174: 시민증 도입 - 기획서 분석, 개발 협의 및 문의 대응, 개발 일정 협의 - QR/결제 적용 시안 디자인 작업 및 전달 | F174: =VLOOKUP(D174,CSR!$D$4:$E$1180,2,FALSE) -> CSR_40300 | G174: 46192 | H174: 1 | I174: =H174*10/190 -> 0.052631579 | J174: 기획자1
A175: 6월 | B175: 신규사업 개발 | C175: 인증플랫폼 | D175: 모바일신분증 고도화 (라인업 확대_시민증 관광증) | E175: MIS 신원인증 안면인증 예외 처리 - 기획서 초안 작성 및 개발 검토 요청 | F175: =VLOOKUP(D175,CSR!$D$4:$E$1180,2,FALSE) -> CSR_40300 | G175: 46192 | H175: 0.5 | I175: =H175*10/190 -> 0.026315789 | J175: 기획자1
A176: 6월 | B176: 신규사업 개발 | C176: 인증플랫폼 | D176: PASS지갑 고도화 | E176: PASS지갑 SDK 업데이트 - 개발 검토 요청 - SDK 마감일정 조율 및 배포 일정 안내 | F176: =VLOOKUP(D176,CSR!$D$4:$E$1180,2,FALSE) -> CSR_40600 | G176: 46182 | H176: 0.2 | I176: =H176*10/190 -> 0.010526316 | J176: 기획자1
A177: 6월 | B177: 서비스 품질관리 | C177: 서비스 운영 | D177: CP 파트너십 관리 (PASS 앱 기획, 디자인, 개발 가이드) | E177: 펫신분증 운영 대응 1. 하위서비스(펫세권) UI 개편 상용 반영 후 테스트 2. CP 데이터 초기화에 따른 PASS 가입 정보 초기화 대응 3. 검수 테스트 데이터 발급 요청 4. 검수앱 배포 요청 및 전달 | F177: =VLOOKUP(D177,CSR!$D$4:$E$1180,2,FALSE) -> CSR_30000 | G177: 46192 | H177: 0.5 | I177: =H177*10/190 -> 0.026315789 | J177: 기획자1
A178: 6월 | B178: 서비스 품질관리 | C178: 서비스 운영 | D178: CP 파트너십 관리 (PASS 앱 기획, 디자인, 개발 가이드) | E178: PASS지갑 운영 대응 1. 검수 증명서 발급 오류 확인 요청 및 테스트 2. 검수 전자고지 PUSH 발송 오류 확인 요청 및 테스트 3. 검수 서비스 진입 오류 확인 요청 및 테스트 4. IP 추가 등록 요청 | F178: =VLOOKUP(D178,CSR!$D$4:$E$1180,2,FALSE) -> CSR_30000 | G178: 46192 | H178: 0.5 | I178: =H178*10/190 -> 0.026315789 | J178: 기획자1
A179: 6월 | B179: 서비스 품질관리 | C179: 서비스 운영 | D179: 업무보고 및 협의 | E179: PASS U+ 월례회의 : 개발항목 협의 | F179: =VLOOKUP(D179,CSR!$D$4:$E$1180,2,FALSE) -> CSR_30600 | G179: 46182 | H179: 0.3 | I179: =H179*10/190 -> 0.015789474 | J179: 기획자1
A180: 6월 | B180: 서비스 품질관리 | C180: 서비스 운영 | D180: LGU+ 요청사항 대응 및 운영 | E180: 신분증 운영 대응 1. 안면인증 실패 통계 공유 - 주차 별 통계 수동 추출 요청, 검증 및 공유 (5월 4주차~5월 5주차) 2. 면허증 작업공지 등록 요청 (1건) 3. 통합인증서버 IMEI 조회 중단에 따른 앱 안내 로직 확인 및 U+ 공유 4. 면허증 가맹점 및 인증 데이터 추출 기준 정리 및 요청 | F180: =VLOOKUP(D180,CSR!$D$4:$E$1180,2,FALSE) -> CSR_30200 | G180: 46192 | H180: 1 | I180: =H180*10/190 -> 0.052631579 | J180: 기획자1
A181: 5월 | B181: 신규사업 개발 | C181: 신규서비스개발 | D181: ㄴPASS안심클라우드 | E181: PASS클라우드 - CP사 운영 SDK 개발 전달 - CVT 이슈 관련 CP사&개발&QA 문의 확인 및 F/U - 구글클라우드 oAuth 이슈 관련 U+ 공유 및 협의 - 서비스 약관 어드민 세팅(검수) - 검수환경 방화벽 해제 요청 건 F/U | F181: =VLOOKUP(D181,CSR!$D$4:$E$1180,2,FALSE) -> CSR_41103 | G181: 46162 | H181: 2 | I181: =H181*10/190 -> 0.10526316 | J181: 기획자2 | L181: 미활용
A182: 5월 | B182: 기능 고도화 | C182: PASS기능개발 | D182: PASS 주소록 기능 개발 | E182: PASS주소록 - 고도화 - 페이백쇼핑 반영 관련 CP사 협의 - 문서공유 오류 수정 관련 검증 - 문서공유 기능 관련 수정사항 CP사 협의(w.폴라리스오피스) | F182: =VLOOKUP(D182,CSR!$D$4:$E$1180,2,FALSE) -> CSR_10800 | G182: 46169 | H182: 2 | I182: =H182*10/190 -> 0.10526316 | J182: 기획자2 | L182: 미활용
A183: 5월 | B183: 서비스 품질관리 | C183: 서비스 운영 | D183: CP 파트너십 관리 (PASS 앱 기획, 디자인, 개발 가이드) | E183: 셀로 - 미사용 회원 삭제 관련 개발 방식 관련 개발&CP 협의 - 일반서비스 검수서버 방화벽 해제 완료 확인 금융혜택 - 통신위성 발사하기 알뜰폰 테스트 진행 및 결과 CP사 회신 | F183: =VLOOKUP(D183,CSR!$D$4:$E$1180,2,FALSE) -> CSR_30000 | G183: 46170 | H183: 1 | I183: =H183*10/190 -> 0.052631579 | J183: 기획자2 | L183: 미활용
A184: 5월 | B184: 기능 고도화 | C184: PASS기능개발 | D184: PASS MY 화면 고도화 | E184: MY 고도화 - 개발 방식 및 운영사항 개발팀 협의 - MY 개선사항 기획서 업데이트 | F184: =VLOOKUP(D184,CSR!$D$4:$E$1180,2,FALSE) -> CSR_10400 | G184: 46171 | H184: 1 | I184: =H184*10/190 -> 0.052631579 | J184: 기획자2 | L184: 미활용
A185: 5월 | B185: 기능 고도화 | C185: PASS기능개발 | D185: PASS 주소록 기능 개발 | E185: PASS주소록 - 신원인증 기능 추가 - CP사 제안서 검토 및 정책 관련 문의 - 기획서 업데이트 | F185: =VLOOKUP(D185,CSR!$D$4:$E$1180,2,FALSE) -> CSR_10800 | G185: 46171 | H185: 1.5 | I185: =H185*10/190 -> 0.078947368 | J185: 기획자2 | L185: 하 | M185: 신원인증 기능 관련 정책 검토 및 문서 정리를 보조적으로 수행
A186: 6월 | B186: 신규사업 개발 | C186: 신규서비스개발 | D186: ㄴPASS안심클라우드 | E186: PASS클라우드 - CVT 이슈 관련 CP사&개발&QA 문의 확인 및 F/U - 구글클라우드 oAuth 이슈 및 스토어 심사 관련 F/U - 서비스 약관 어드민 세팅(상용) | F186: =VLOOKUP(D186,CSR!$D$4:$E$1180,2,FALSE) -> CSR_41103 | G186: 46178 | H186: 2.5 | I186: =H186*10/190 -> 0.13157895 | J186: 기획자2 | L186: 미활용
A187: 6월 | B187: 기능 고도화 | C187: PASS기능개발 | D187: PASS 주소록 기능 개발 | E187: PASS주소록 - 고도화 - 8월 버전 기획서 초안 작성 - 페이백쇼핑 반영 관련 CP사 협의 - 온보딩 가이드 디자인 요청 및 검수 | F187: =VLOOKUP(D187,CSR!$D$4:$E$1180,2,FALSE) -> CSR_10800 | G187: 46178 | H187: 1 | I187: =H187*10/190 -> 0.052631579 | J187: 기획자2 | L187: 미활용
A188: 6월 | B188: 기능 고도화 | C188: PASS기능개발 | D188: ㄴPASS MAIN 개편 | E188: 메인 홈 개편 - 기획 요건 정리 및 기획서 초안 작성 | F188: =VLOOKUP(D188,CSR!$D$4:$E$1180,2,FALSE) -> CSR_10201 | G188: 46184 | H188: 2 | I188: =H188*10/190 -> 0.10526316 | J188: 기획자2 | L188: 하 | M188: 기획서 초안 작성 및 UI 구성 방향 검토 시 보조적으로 활용함
A189: 6월 | B189: 서비스 품질관리 | C189: 서비스 운영 | D189: 업무보고 및 협의 | E189: PASS U+ 월간회의 : 개발항목 협의 | F189: =VLOOKUP(D189,CSR!$D$4:$E$1180,2,FALSE) -> CSR_30600 | G189: 46182 | H189: 0.3 | I189: =H189*10/190 -> 0.015789474 | J189: 기획자2 | L189: 미활용
A190: 6월 | B190: 서비스 품질관리 | C190: 서비스 운영 | D190: LGU+ 요청사항 대응 및 운영 | E190: PASS주소록 서비스 소개서 작성 및 전달 | F190: =VLOOKUP(D190,CSR!$D$4:$E$1180,2,FALSE) -> CSR_30200 | G190: 46183 | H190: 0.2 | I190: =H190*10/190 -> 0.010526316 | J190: 기획자2 | L190: 미활용
A191: 6월 | B191: 기능 고도화 | C191: PASS기능개발 | D191: PASS 주소록 기능 개발 | E191: PASS주소록 - 신원인증 기능 추가 - CP사 제안서 검토 및 정책 관련 문의 - 기획서 업데이트 | F191: =VLOOKUP(D191,CSR!$D$4:$E$1180,2,FALSE) -> CSR_10800 | G191: 46184 | H191: 1.5 | I191: =H191*10/190 -> 0.078947368 | J191: 기획자2 | L191: 하 | M191: 신원인증 기능 관련 정책 검토 및 문서 정리를 보조적으로 수행
A192: 6월 | B192: 서비스 품질관리 | C192: 서비스 운영 | D192: CP 파트너십 관리 (PASS 앱 기획, 디자인, 개발 가이드) | E192: 셀로 - 미사용 회원 삭제 관련 개발 방식 관련 개발&CP 협의 - 검수환경 탈퇴 오류 관련 F/U 폴라리스오피스 - 오피스스캐너 관련 회의 웹툰 - 검수환경 진입 오류 관련 F/U | F192: =VLOOKUP(D192,CSR!$D$4:$E$1180,2,FALSE) -> CSR_30000 | G192: 46188 | H192: 0.5 | I192: =H192*10/190 -> 0.026315789 | J192: 기획자2 | L192: 미활용
A193: 6월 | B193: 신규사업 개발 | C193: 신규서비스개발 | D193: ㄴPASS안심클라우드 | E193: PASS클라우드 - 일정 공유 및 8월 개발 항목 확인 - 검수환경 진입 오류 관련 CP사 확인 - 최종 기획서 수급 일정 문의 | F193: =VLOOKUP(D193,CSR!$D$4:$E$1180,2,FALSE) -> CSR_41103 | G193: 46191 | H193: 1.5 | I193: =H193*10/190 -> 0.078947368 | J193: 기획자2 | L193: 미활용
A194: 6월 | B194: 기능 고도화 | C194: PASS기능개발 | D194: ㄴPASS MAIN 개편 | E194: 메인 홈 개편 - 기획 요건 정리 및 기획서 초안 작성 - 메인 홈 디자인 요청 | F194: =VLOOKUP(D194,CSR!$D$4:$E$1180,2,FALSE) -> CSR_10201 | G194: 46192 | H194: 2 | I194: =H194*10/190 -> 0.10526316 | J194: 기획자2 | L194: 하 | M194: 기획서 초안 작성 및 UI 구성 방향 검토 시 보조적으로 활용함
A195: 6월 | B195: 기능 고도화 | C195: 신규서비스개발 | D195: PASS 주소록 기능 개발 | E195: 온보딩페이지내 화면 현행화 적용 | F195: =VLOOKUP(D195,[1]CSR!$D$4:$E$1180,2,FALSE) -> #N/A | G195: 46171 | H195: 3 | I195: =H195*10/190 -> 0.15789474 | J195: 디자이너2 | L195: 미활용 | M195: 기존 작업된 화면 활용하였음
...

Sheet AI활용 현황 분석_유플러스 작성 예정
A1: ■ AI 활용 현황 분석 Dashboard (26년 05월) _유플러스 작성 예정
A3: [A] 구분별 AI 활용 수준 현황
A4: 구분 | B4: 전체 건수 | C4: 상 | D4: 중 | E4: 하 | F4: 미활용 | G4: AI활용율 (상+중)
A5: 기능 고도화 | B5: 156 | C5: 52 | D5: 48 | E5: 30 | F5: 26 | G5: 64.1%
A6: 마케팅 | B6: 24 | C6: 4 | D6: 8 | E6: 7 | F6: 5 | G6: 50.0%
A7: 서비스 품질관리 | B7: 52 | C7: 14 | D7: 18 | E7: 12 | F7: 8 | G7: 61.5%
A8: 신규사업 개발 | B8: 30 | C8: 10 | D8: 9 | E8: 6 | F8: 5 | G8: 63.3%
A9: 합계 | B9: 262 | C9: 80 | D9: 83 | E9: 55 | F9: 44 | G9: 62.2%
A12: [B] 역할군별 AI 활용 수준
A13: 역할군 | B13: 인원 | C13: 전체 M/M | D13: 상(%) | E13: 중(%) | F13: 하(%) | G13: 미활용(%) | H13: 활용도 평가
A14: Android 개발 | B14: 5 | C14: 5 | D14: 58% | E14: 30% | F14: 8% | G14: 4% | H14: 우수
A15: iOS 개발 | B15: 4 | C15: 4 | D15: 55% | E15: 32% | F15: 10% | G15: 3% | H15: 우수
A16: 서버 개발 | B16: 7 | C16: 7 | D16: 35% | E16: 40% | F16: 18% | G16: 7% | H16: 양호
A17: 기획 | B17: 4 | C17: 4 | D17: 15% | E17: 45% | F17: 30% | G17: 10% | H17: 양호
A18: QA | B18: 2 | C18: 2 | D18: 50% | E18: 35% | F18: 10% | G18: 5% | H18: 우수
A19: 디자이너 | B19: 2 | C19: 1.95 | D19: 5% | E19: 20% | F19: 40% | G19: 35% | H19: 개선필요
A20: PM/퍼블리셔/CS 등 | B20: 7 | C20: 2.58 | D20: 10% | E20: 25% | F20: 35% | G20: 30% | H20: 개선필요
A23: [C] AI 활용 주요 사례 (Best Practice)
A24: No | B24: 업무 영역 | C24: AI 활용 내용 | D24: 활용 수준 | E24: 개선 효과 (정성적)
A25: 1 | B25: AOS/iOS 앱 개발 | C25: Copilot 활용 반복 코드 패턴 자동완성 및 코드리뷰 보조 | D25: 상 | E25: 코드 작성 속도 향상, 코드 품질 일관성 개선
A26: 2 | B26: 서버 API 개발 | C26: Copilot 활용 API 엔드포인트 코드 생성 및 단위테스트 보조 | D26: 상 | E26: API 개발 속도 향상, 테스트 커버리지 확대
A27: 3 | B27: QA 테스트 | C27: AI 기반 테스트 시나리오 초안 자동 생성 후 검토·보완 | D27: 상 | E27: 테스트케이스 작성 시간 단축, 커버리지 향상
A28: 4 | B28: 기획·문서화 | C28: 기획서/요구사항 정의서 초안 AI 생성 후 검토·수정 | D28: 중 | E28: 기획 리드타임 단축, 문서 표준화 개선
A29: 5 | B29: 서버 운영 | C29: 장애 대응 로그 분석 시 AI 활용, 모니터링 리포트 초안 생성 | D29: 중 | E29: 장애 분석 시간 단축, 리포트 품질 향상
A30: 6 | B30: 마케팅/데이터 | C30: GA4 데이터 분석 시 AI 활용, VOC 키워드 자동 분류 | D30: 중 | E30: 데이터 분석 효율화, 인사이트 도출 속도 향상
A31: 7 | B31: MM 관리·보고 | C31: AI 활용 MM 집계/분석 자동화, 월간 리포트 초안 생성 | D31: 상 | E31: 관리 업무 효율화, 데이터 기반 의사결정 지원
A34: [D] 월별 AI 활용 추이 (8차년도)
A35: 항목 | B35: 25.11월 | C35: 25.12월 | D35: 26.01월 | E35: 26.02월 | F35: 26.03월 | G35: 26.04월 | H35: 26.05월 | I35: 추이
A36: 전체 건수 | B36: 237 | C36: 211 | D36: 227 | E36: 208 | F36: 233 | G36: 234 | H36: 262 | I36: →
A37: AI활용 건수 (상+중) | B37: 95 | C37: 98 | D37: 112 | E37: 118 | F37: 135 | G37: 142 | H37: 163 | I37: ↑
A38: AI 활용율 | B38: 40.1% | C38: 46.4% | D38: 49.3% | E38: 56.7% | F38: 57.9% | G38: 60.7% | H38: 62.2% | I38: ↑↑
A39: 상(적극활용) | B39: 15.2% | C39: 18.0% | D39: 22.0% | E39: 25.0% | F39: 27.0% | G39: 29.0% | H39: 30.5% | I39: ↑
A42: [E] AI 활용 개선 방향
A43: ✅ 현재 성과 | B43: 전체 업무의 62.2%에서 AI 활용 중 (전월 대비 +1.5%p 증가), 개발 영역 중심으로 적극 활용 정착
A44: ✅ 강점 영역 | B44: 앱 개발(AOS/iOS) 및 QA 영역에서 AI 활용 수준 "우수" 달성 → Copilot 코드 생성·테스트 자동화 중심
A45: 📌 개선 필요 | B45: 디자이너·PM 영역 AI 활용 "개선필요" → 디자인 AI 도구 도입 검토, PM 보고 자동화 확대 필요
A46: 📌 확대 방향 | B46: 서버 운영 영역 자동화 강화 (장애 예측, 리포트 자동 생성), 기획 영역 AI 활용 고도화 (PRD 자동 생성 등)
A47: 🎯 목표 | B47: 8차년도 종료 시점(26.10월) AI 활용율 75% 이상, 전 역할군 "양호" 이상 달성

Sheet 26년05월
A1: 월 | B1: 구분 | C1: 중점추진과제 | D1: 상세추진과제 | E1: 상세 추진 내용 | F1: CSR ID | G1: 완료일시 | H1: 투입M/D | I1: 투입M/M | J1: 처리자 | K1: 비고
A2: 4월 | B2: 기능 고도화 | C2: PASS기능개발 | D2: 서비스 개발 | E2: 모바일신분증 디자인 개편, 반려동물 신분증 서비스 추가, 병원QR제시형 추가, AOS 14 대응 등 AOS 기능 개발검토 | F2: =VLOOKUP(D2,CSR!$D$4:$E$1180,2,FALSE) -> CSR_11300 | G2: 46136 | H2: 2 | I2: =H2*10/190 -> 0.10526316 | J2: Android개발자1
A3: 4월 | B3: 기능 고도화 | C3: PASS기능개발 | D3: 서비스 개발 | E3: 명의도용방지 가입자정보 조회 KAIT 미응답 Alert 에러코드 누락과 비밀번호 변경 화면 미이동 이슈 수정 등 AOS 보완 개발 | F3: =VLOOKUP(D3,CSR!$D$4:$E$1180,2,FALSE) -> CSR_11300 | G3: 46136 | H3: 2 | I3: =H3*10/190 -> 0.10526316 | J3: Android개발자1
A4: 5월 | B4: 기능 고도화 | C4: PASS기능개발 | D4: 서비스 개발 | E4: PASS Android API 응답 모니터링 앱 요구사항 초안, AOS 운영 이슈 정리, 다음 차수 반영 범위 검토 등 AOS 기능 개발검토 | F4: =VLOOKUP(D4,CSR!$D$4:$E$1180,2,FALSE) -> CSR_11300 | G4: 46143 | H4: 2 | I4: =H4*10/190 -> 0.10526316 | J4: Android개발자1
A5: 5월 | B5: 서비스 품질관리 | C5: 서비스 운영 | D5: LGU+ 요청사항 대응 및 운영 | E5: 운영 이슈 확인과 서비스 연계 화면 점검, 민원 대응 항목 정리 등 운영 지원 | F5: =VLOOKUP(D5,CSR!$D$4:$E$1180,2,FALSE) -> CSR_30200 | G5: 46143 | H5: 2 | I5: =H5*10/190 -> 0.10526316 | J5: Android개발자1
A6: 5월 | B6: 서비스 품질관리 | C6: 서비스 운영 | D6: LGU+ 요청사항 대응 및 운영 | E6: 방통위 증적 자료 준비, PASS 앱 운영 확인 항목 정리, 모바일운전면허 요청 대응 연계 검토 등 운영 지원 | F6: =VLOOKUP(D6,CSR!$D$4:$E$1180,2,FALSE) -> CSR_30200 | G6: 46150 | H6: 2 | I6: =H6*10/190 -> 0.10526316 | J6: Android개발자1
A7: 5월 | B7: 서비스 품질관리 | C7: 서비스 운영 | D7: LGU+ 요청사항 대응 및 운영 | E7: 서비스 연계 화면 점검과 모의해킹 취약점 대응 연계 확인 등 AOS 운영 지원 | F7: =VLOOKUP(D7,CSR!$D$4:$E$1180,2,FALSE) -> CSR_30200 | G7: 46150 | H7: 2 | I7: =H7*10/190 -> 0.10526316 | J7: Android개발자1
A8: 5월 | B8: 기능 고도화 | C8: PASS기능개발 | D8: 서비스 개발 | E8: PASS 앱 운영 확인 항목 정리, 클라이언트 반영 문서 점검, 연계 화면 흐름 확인 등 AOS 기능 개발검토 | F8: =VLOOKUP(D8,CSR!$D$4:$E$1180,2,FALSE) -> CSR_11300 | G8: 46157 | H8: 2 | I8: =H8*10/190 -> 0.10526316 | J8: Android개발자1
A9: 5월 | B9: 서비스 품질관리 | C9: 서비스 운영 | D9: LGU+ 요청사항 대응 및 운영 | E9: 운영 이슈 확인과 모바일운전면허 요청 대응 연계 정리, 서비스 화면 점검 등 운영 지원 | F9: =VLOOKUP(D9,CSR!$D$4:$E$1180,2,FALSE) -> CSR_30200 | G9: 46157 | H9: 2 | I9: =H9*10/190 -> 0.10526316 | J9: Android개발자1
A10: 5월 | B10: 기능 고도화 | C10: PASS기능개발 | D10: ㄴ26년 6월 앱 배포 검수 | E10: AOS 운영 이슈 확인, 서비스 연계 화면 점검, 민원 대응 항목 정리 등 AOS 기능 개발검토 | F10: =VLOOKUP(D10,CSR!$D$4:$E$1180,2,FALSE) -> CSR_11416 | G10: 46162 | H10: 2 | I10: =H10*10/190 -> 0.10526316 | J10: Android개발자1
A11: 5월 | B11: 서비스 품질관리 | C11: 서비스 운영 | D11: LGU+ 요청사항 대응 및 운영 | E11: 운영 이슈 후속 정리와 모바일신분증 연계 확인, 서비스 화면 점검 등 운영 지원 | F11: =VLOOKUP(D11,CSR!$D$4:$E$1180,2,FALSE) -> CSR_30200 | G11: 46162 | H11: 1 | I11: =H11*10/190 -> 0.052631579 | J11: Android개발자1
A12: 4월 | B12: 신규사업 개발 | C12: 신규서비스개발 | D12: ㄴPASS안심클라우드 | E12: PASS클라우드 추가, MY개편 고도화, PASS 부가서비스 재동의 프로세스 수정, 서비스영역 문의하기 인앱브라우저 연동 등 AOS 기능 개발검토 | F12: =VLOOKUP(D12,CSR!$D$4:$E$1180,2,FALSE) -> CSR_41103 | G12: 46136 | H12: 2 | I12: =H12*10/190 -> 0.10526316 | J12: Android개발자2
A13: 4월 | B13: 기능 고도화 | C13: PASS기능개발 | D13: ㄴ외부플랫폼 진입 시 브릿지 페이지 | E13: 외부플랫폼 브릿지와 MY개편 연계 항목 보완, 기능 적용 후 화면 확인까지 포함한 AOS 보완 개발 | F13: =VLOOKUP(D13,CSR!$D$4:$E$1180,2,FALSE) -> CSR_11314 | G13: 46136 | H13: 2 | I13: =H13*10/190 -> 0.10526316 | J13: Android개발자2
... A94: 5월 | B94: 기능 고도화 | C94: PASS기능개발 | D94: ㄴ26년 6월 앱 배포 검수 | E94: 이벤트·광고 알림 토글 미동작과 QR 스캔 후 인증내역 미적재 이슈 수정, 내부 검증 병행 iOS 기능 정비 | F94: =VLOOKUP(D94,CSR!$D$4:$E$1180,2,FALSE) -> CSR_11416 | G94: 46162 | H94: 1 | I94: =H94*10/190 -> 0.052631579 | J94: iOS개발자4
A95: 4월 | B95: 기능 고도화 | C95: PASS기능개발 | D95: ㄴ26년 6월 앱 배포 검수 | E95: 6월 앱 DVT 설계 - 개편 항목 테스트 케이스 설계 , 테스트 데이터 준비, 테스트 환경 설정 | F95: =VLOOKUP(D95,CSR!$D$4:$E$1180,2,FALSE) -> CSR_11416 | G95: 4월 24일 | H95: 3 | I95: =H95*10/190 -> 0.15789474 | J95: QA1
A96: 4월 | B96: 기능 고도화 | C96: PASS기능개발 | D96: ㄴ26년 6월 앱 배포 검수 | E96: 6월 앱 DVT 수행 - 인앱 브라우저, MY 고도화, 오늘의게임, 신분증 가맹점 표기 정책 개선, 계좌인증 금융기관 선택화면 UIUX 개선 | F96: =VLOOKUP(D96,CSR!$D$4:$E$1180,2,FALSE) -> CSR_11416 | G96: 4월 30일 | H96: 4 | I96: =H96*10/190 -> 0.21052632 | J96: QA1
A97: 5월 | B97: 기능 고도화 | C97: PASS기능개발 | D97: ㄴ26년 6월 앱 배포 검수 | E97: 6월 앱 DVT 수행 - MY 고도화, PASS주소록 고도화, PASS안심클라우드, MIS 선택 업데이트 기능, 외부플랫폼 브릿지 페이지 | F97: =VLOOKUP(D97,CSR!$D$4:$E$1180,2,FALSE) -> CSR_11416 | G97: 5월 8일 | H97: 4 | I97: =H97*10/190 -> 0.21052632 | J97: QA1
A98: 5월 | B98: 기능 고도화 | C98: PASS기능개발 | D98: ㄴ26년 6월 앱 배포 검수 | E98: 6월 앱 DVT 수행 - MY 고도화, PASS주소록 고도화, PASS안심클라우드, 유무료 서비스 동의화면 개선 | F98: =VLOOKUP(D98,CSR!$D$4:$E$1180,2,FALSE) -> CSR_11416 | G98: 5월 14일 | H98: 4 | I98: =H98*10/190 -> 0.21052632 | J98: QA1
A99: 5월 | B99: 기능 고도화 | C99: PASS기능개발 | D99: ㄴ26년 6월 앱 배포 검수 | E99: 6월 앱 DVT 수행 - PASS주소록 고도화, PASS안심클라우드, 업데이트 후 서비스 진입 개선 | F99: =VLOOKUP(D99,CSR!$D$4:$E$1180,2,FALSE) -> CSR_11416 | G99: 5월 18일 | H99: 2 | I99: =H99*10/190 -> 0.10526316 | J99: QA1
A100: 5월 | B100: 기능 고도화 | C100: PASS기능개발 | D100: ㄴ26년 6월 앱 배포 검수 | E100: 6월 앱 DVT 후속 점검 - CP 이슈 수정 확인, 산출물 점검, 개편 기능 재검토 | F100: =VLOOKUP(D100,CSR!$D$4:$E$1180,2,FALSE) -> CSR_11416 | G100: 5월 20일 | H100: 2 | I100: =H100*10/190 -> 0.10526316 | J100: QA1
A101: 4월 | B101: 기능 고도화 | C101: PASS기능개발 | D101: ㄴ26년 6월 앱 배포 검수 | E101: 26년 6월 개편 앱 앱 DVT 대응 - 6월 개편 앱 설계 | F101: =VLOOKUP(D101,CSR!$D$4:$E$1180,2,FALSE) -> CSR_11416 | G101: 4월 24일 | H101: 3 | I101: =H101*10/190 -> 0.15789474 | J101: QA2
A102: 4월 | B102: 기능 고도화 | C102: PASS기능개발 | D102: ㄴ26년 6월 앱 배포 검수 | E102: 26년 6월 개편 앱 앱 DVT 대응 - DVT 수행 | F102: =VLOOKUP(D102,CSR!$D$4:$E$1180,2,FALSE) -> CSR_11416 | G102: 4월 30일 | H102: 4 | I102: =H102*10/190 -> 0.21052632 | J102: QA2
A103: 5월 | B103: 기능 고도화 | C103: PASS기능개발 | D103: ㄴ26년 6월 앱 배포 검수 | E103: 26년 6월 개편 앱 앱 DVT 대응 - DVT 수행 | F103: =VLOOKUP(D103,CSR!$D$4:$E$1180,2,FALSE) -> CSR_11416 | G103: 5월 8일 | H103: 4 | I103: =H103*10/190 -> 0.21052632 | J103: QA2
A104: 5월 | B104: 기능 고도화 | C104: PASS기능개발 | D104: ㄴ26년 6월 앱 배포 검수 | E104: 26년 6월 개편 앱 앱 DVT 대응 - DVT 수행 | F104: =VLOOKUP(D104,CSR!$D$4:$E$1180,2,FALSE) -> CSR_11416 | G104: 5월 14일 | H104: 4 | I104: =H104*10/190 -> 0.21052632 | J104: QA2
A105: 5월 | B105: 기능 고도화 | C105: PASS기능개발 | D105: ㄴ26년 6월 앱 배포 검수 | E105: 26년 6월 개편 앱 앱 DVT 대응 - DVT 수행 | F105: =VLOOKUP(D105,CSR!$D$4:$E$1180,2,FALSE) -> CSR_11416 | G105: 5월 18일 | H105: 2 | I105: =H105*10/190 -> 0.10526316 | J105: QA2
A106: 5월 | B106: 기능 고도화 | C106: PASS기능개발 | D106: ㄴ26년 6월 앱 배포 검수 | E106: 26년 6월 개편 앱 앱 DVT 대응 - CP 이슈 등록 및 수정 확인, 개편 기능 크로스체크 | F106: =VLOOKUP(D106,CSR!$D$4:$E$1180,2,FALSE) -> CSR_11416 | G106: 5월 20일 | H106: 2 | I106: =H106*10/190 -> 0.10526316 | J106: QA2
A107: 4월 | B107: 서비스 품질관리 | C107: 서비스 운영 | D107: 업무보고 및 협의 | E107: PASS전략파트너 개발 관련 업무보고 및 협의 - 내부/외부 회의 및 협의 | F107: =VLOOKUP(D107,CSR!$D$4:$E$1180,2,FALSE) -> CSR_30600 | G107: 46136 | H107: 4 | I107: =H107*10/190 -> 0.21052632 | J107: 개발PM
A108: 5월 | B108: 서비스 품질관리 | C108: 서비스 운영 | D108: 업무보고 및 협의 | E108: PASS전략파트너 개발 관련 업무보고 및 협의 - 내부/외부 회의 및 협의 | F108: =VLOOKUP(D108,CSR!$D$4:$E$1180,2,FALSE) -> CSR_30600 | G108: 46143 | H108: 4 | I108: =H108*10/190 -> 0.21052632 | J108: 개발PM
A109: 5월 | B109: 서비스 품질관리 | C109: 서비스 운영 | D109: 업무보고 및 협의 | E109: PASS전략파트너 개발 관련 업무보고 및 협의 - 내부/외부 회의 및 협의 | F109: =VLOOKUP(D109,CSR!$D$4:$E$1180,2,FALSE) -> CSR_30600 | G109: 46150 | H109: 4 | I109: =H109*10/190 -> 0.21052632 | J109: 개발PM
A110: 5월 | B110: 서비스 품질관리 | C110: 서비스 운영 | D110: 업무보고 및 협의 | E110: PASS전략파트너 개발 관련 업무보고 및 협의 - 내부/외부 회의 및 협의 | F110: =VLOOKUP(D110,CSR!$D$4:$E$1180,2,FALSE) -> CSR_30600 | G110: 46157 | H110: 4 | I110: =H110*10/190 -> 0.21052632 | J110: 개발PM
A111: 5월 | B111: 서비스 품질관리 | C111: 서비스 운영 | D111: 업무보고 및 협의 | E111: PASS전략파트너 개발 관련 업무보고 및 협의 - 내부/외부 회의 및 협의 | F111: =VLOOKUP(D111,CSR!$D$4:$E$1180,2,FALSE) -> CSR_30600 | G111: 46162 | H111: 3 | I111: =H111*10/190 -> 0.15789474 | J111: 개발PM
A112: 4월 | B112: 서비스 품질관리 | C112: 서비스 운영 | D112: 업무보고 및 협의 | E112: PASS전략파트너 개발 관련 업무보고 및 협의 - 내부/외부 회의 및 협의 | F112: =VLOOKUP(D112,CSR!$D$4:$E$1180,2,FALSE) -> CSR_30600 | G112: 46136 | H112: 3 | I112: =H112*10/190 -> 0.15789474 | J112: 기획PM
A113: 4월 | B113: 서비스 품질관리 | C113: 서비스 운영 | D113: 업무보고 및 협의 | E113: PASS전략파트너 개발 관련 업무보고 및 협의 - 내부/외부 회의 및 협의 | F113: =VLOOKUP(D113,CSR!$D$4:$E$1180,2,FALSE) -> CSR_30600 | G113: 46142 | H113: 3 | I113: =H113*10/190 -> 0.15789474 | J113: 기획PM
A114: 5월 | B114: 서비스 품질관리 | C114: 서비스 운영 | D114: 업무보고 및 협의 | E114: PASS전략파트너 개발 관련 업무보고 및 협의 - 내부/외부 회의 및 협의 | F114: =VLOOKUP(D114,CSR!$D$4:$E$1180,2,FALSE) -> CSR_30600 | G114: 46150 | H114: 3 | I114: =H114*10/190 -> 0.15789474 | J114: 기획PM
A115: 5월 | B115: 신규사업 개발 | C115: 신규서비스 개발 | D115: ㄴ스마트청구서 개발 | E115: 스마트청구서 세부 기획 | F115: =VLOOKUP(D115,CSR!$D$4:$E$1180,2,FALSE) -> CSR_41201 | G115: 46162 | H115: 2 | I115: =H115*10/190 -> 0.10526316 | J115: 기획PM
A116: 5월 | B116: 서비스 품질관리 | C116: 서비스 운영 | D116: 업무보고 및 협의 | E116: PASS전략파트너 개발 관련 업무보고 및 협의 - 내부/외부 회의 및 협의 | F116: =VLOOKUP(D116,CSR!$D$4:$E$1180,2,FALSE) -> CSR_30600 | G116: 46157 | H116: 3 | I116: =H116*10/190 -> 0.15789474 | J116: 기획PM
A117: 5월 | B117: 기능고도화 | C117: PASS기능개발 | D117: PASS UI/UX 개선 | E117: PASS UI/UX 협의를 위한 리스트 작성 | F117: =VLOOKUP(D117,CSR!$D$4:$E$1180,2,FALSE) -> CSR_11500 | G117: 46156 | H117: 2 | I117: =H117*10/190 -> 0.10526316 | J117: 기획PM
A118: 5월 | B118: 신규사업 개발 | C118: 신규서비스 개발 | D118: ㄴB2C PASS 보안서비스 | E118: PASS앱 내 보안서비스 추가를 위한 사전 기획 작업 | F118: =VLOOKUP(D118,CSR!$D$4:$E$1180,2,FALSE) -> CSR_41202 | G118: 46157 | H118: 3 | I118: =H118*10/190 -> 0.15789474 | J118: 기획PM
... A149: 5월 | B149: 서비스 품질관리 | C149: 서비스 운영 | D149: CP 파트너십 관리 (PASS 앱 기획, 디자인, 개발 가이드) | E149: 오피스도우미 SDK 업데이트 - 검수앱 테스트 | F149: =VLOOKUP(D149,CSR!$D$4:$E$1180,2,FALSE) -> CSR_30000 | G149: 46150 | H149: 0.5 | I149: =H149*10/190 -> 0.026315789 | J149: 기획자3
A150: 5월 | B150: 마케팅 | C150: 마케팅 관련 고도화 및 지원 | D150: GA4 컨텐츠 그룹핑 반영 및 운영 지원 | E150: 26년 6월 업데이트용 GA4태깅 문서 작성 - 태깅 검수 및 수정 팔요 사항 전달 | F150: =VLOOKUP(D150,CSR!$D$4:$E$1180,2,FALSE) -> CSR_20400 | G150: 46154 | H150: 1.5 | I150: 0.052631579 | J150: 기획자3
...

Sheet 26년04월
A1: 월 | B1: 구분 | C1: 중점추진과제 | D1: 상세추진과제 | E1: 상세 추진 내용 | F1: CSR ID | G1: 완료일시 | H1: 투입M/D | I1: 투입M/M | J1: 처리자 | K1: 비고
A2: 3월 | B2: 기능 고도화 | C2: PASS기능개발 | D2: 서비스 개발 | E2: PASS주소록, 인앱브라우저, 오피스도우미 SDK 반영, 기능 구조 검토 등 AOS 주요 항목 개발검토 | F2: =VLOOKUP(D2,CSR!$D$4:$E$1180,2,FALSE) -> CSR_11300 | G2: 46108 | H2: 3 | I2: =H2*10/190 -> 0.15789474 | J2: Android개발자1
A3: 3월 | B3: 기능 고도화 | C3: PASS기능개발 | D3: ㄴ업데이트 후 서비스 진입 개선 | E3: 앱 업데이트 후 약관 재동의 팝업 노출과 웹뷰 히스토리 동작 이슈 보완 개발 | F3: =VLOOKUP(D3,CSR!$D$4:$E$1180,2,FALSE) -> CSR_11315 | G3: 46108 | H3: 2 | I3: =H3*10/190 -> 0.10526316 | J3: Android개발자1
A4: 4월 | B4: 기능 고도화 | C4: PASS기능개발 | D4: 서비스 개발 | E4: 외부플랫폼 브릿지 페이지 추가 검토, 계좌인증 은행 로고 변경 요청 반영, 화면 흐름 정리 등 AOS 기능 개발검토 | F4: =VLOOKUP(D4,CSR!$D$4:$E$1180,2,FALSE) -> CSR_11300 | G4: 46115 | H4: 3 | I4: =H4*10/190 -> 0.15789474 | J4: Android개발자1
A5: 4월 | B5: 서비스 품질관리 | C5: 서비스 운영 | D5: LGU+ 요청사항 대응 및 운영 | E5: bitbucket 계정 신청, iOS 운전면허 오류 팝업 이슈 공유, AOS 배터리 급방전 이슈 정리 등 운영 지원 | F5: =VLOOKUP(D5,CSR!$D$4:$E$1180,2,FALSE) -> CSR_30200 | G5: 46115 | H5: 2 | I5: =H5*10/190 -> 0.10526316 | J5: Android개발자1
A6: 4월 | B6: 기능 고도화 | C6: PASS기능개발 | D6: 서비스 개발 | E6: 외부플랫폼 브릿지 페이지 추가 검토, 계좌인증 은행 로고 변경 요청 반영, 연계 화면 흐름 정리 등 AOS 기능 개발검토 | F6: =VLOOKUP(D6,CSR!$D$4:$E$1180,2,FALSE) -> CSR_11300 | G6: 46122 | H6: 3 | I6: =H6*10/190 -> 0.15789474 | J6: Android개발자1
A7: 4월 | B7: 서비스 품질관리 | C7: 서비스 운영 | D7: LGU+ 요청사항 대응 및 운영 | E7: bitbucket 계정 신청, iOS 운전면허 오류 팝업 이슈 공유, AOS 배터리 급방전 이슈 정리 등 운영 지원 | F7: =VLOOKUP(D7,CSR!$D$4:$E$1180,2,FALSE) -> CSR_30200 | G7: 46122 | H7: 2 | I7: =H7*10/190 -> 0.10526316 | J7: Android개발자1
A8: 4월 | B8: 기능 고도화 | C8: PASS기능개발 | D8: 서비스 개발 | E8: 외부플랫폼 브릿지 페이지, 안드로이드 16 대응 SDK 확인, 화면 연계 흐름 검토 등 AOS 기능 개발검토 | F8: =VLOOKUP(D8,CSR!$D$4:$E$1180,2,FALSE) -> CSR_11300 | G8: 46132 | H8: 2 | I8: =H8*10/190 -> 0.10526316 | J8: Android개발자1
A9: 4월 | B9: 서비스 품질관리 | C9: 서비스 운영 | D9: LGU+ 요청사항 대응 및 운영 | E9: bitbucket 계정 전환 후속, AOS 운영 이슈 정리, 모바일운전면허 요청 대응 연계 확인 등 운영 지원 | F9: =VLOOKUP(D9,CSR!$D$4:$E$1180,2,FALSE) -> CSR_30200 | G9: 46132 | H9: 2 | I9: =H9*10/190 -> 0.10526316 | J9: Android개발자1
A10: 3월 | B10: 기능 고도화 | C10: PASS기능개발 | D10: 서비스 개발 | E10: PASS클라우드, 인앱브라우저, MY개편, 전자고지 열람율 개선 등 AOS 핵심 기능 검토 및 구조 설계 | F10: =VLOOKUP(D10,CSR!$D$4:$E$1180,2,FALSE) -> CSR_11300 | G10: 46108 | H10: 3 | I10: =H10*10/190 -> 0.15789474 | J10: Android개발자2
A11: 3월 | B11: 기능 고도화 | C11: PASS기능개발 | D11: PASS 주소록 기능 개발 | E11: 오피스도우미 SDK 업데이트 AOS 기능 선행 개발 | F11: =VLOOKUP(D11,CSR!$D$4:$E$1180,2,FALSE) -> CSR_10800 | G11: 46108 | H11: 2 | I11: =H11*10/190 -> 0.10526316 | J11: Android개발자2
A12: 4월 | B12: 기능 고도화 | C12: PASS기능개발 | D12: 서비스 개발 | E12: PASS클라우드, 오피스도우미 SDK 업데이트, 애드몹 광고 형식 추가 등 AOS 핵심 기능 검토 및 구조 설계 | F12: =VLOOKUP(D12,CSR!$D$4:$E$1180,2,FALSE) -> CSR_11300 | G12: 46115 | H12: 3 | I12: =H12*10/190 -> 0.15789474 | J12: Android개발자2
A13: 4월 | B13: 기능 고도화 | C13: PASS기능개발 | D13: 서비스 개발 | E13: 신분증 가맹점 표기 정책 개선 AOS 기능 선행 개발 | F13: =VLOOKUP(D13,CSR!$D$4:$E$1180,2,FALSE) -> CSR_11300 | G13: 46115 | H13: 2 | I13: =H13*10/190 -> 0.10526316 | J13: Android개발자2
... A73: 4월 | B73: 기능 고도화 | C73: PASS기능개발 | D73: ㄴ유·무료 서비스 동의화면 개선 | E73: 유·무료 서비스 동의화면 개선 iOS 기능 후속 보완 개발 | F73: =VLOOKUP(D73,CSR!$D$4:$E$1180,2,FALSE) -> CSR_11305 | G73: 46132 | H73: 2 | I73: =H73*10/190 -> 0.10526316 | J73: iOS개발자4
A74: 4월 | B74: 서비스 품질관리 | C74: 서비스 운영 | D74: VOC 처리, 대응 및 사용자 공지 | E74: CS문의 대응 | F74: =VLOOKUP(D74,CSR!$D$4:$E$1180,2,FALSE) -> CSR_30300 | G74: 4월 20일 | H74: 2 | I74: =H74*10/190 -> 0.10526316 | J74: CS1
A75: 4월 | B75: 서비스 품질관리 | C75: 서비스 운영 | D75: VOC 처리, 대응 및 사용자 공지 | E75: CS문의 대응 | F75: =VLOOKUP(D75,CSR!$D$4:$E$1180,2,FALSE) -> CSR_30300 | G75: 4월 20일 | H75: 2 | I75: =H75*10/190 -> 0.10526316 | J75: CS2
A76: 4월 | B76: 서비스 품질관리 | C76: 서비스 운영 | D76: VOC 처리, 대응 및 사용자 공지 | E76: CS문의 대응 | F76: =VLOOKUP(D76,CSR!$D$4:$E$1180,2,FALSE) -> CSR_30300 | G76: 4월 20일 | H76: 2 | I76: =H76*10/190 -> 0.10526316 | J76: CS3
A77: 3월 | B77: 기능 고도화 | C77: PASS기능개발 | D77: ㄴ26년 4월 앱 배포 검수 | E77: 4월 배포 건 DVT 검증 - 모바일지갑 IMEI 예외처리, iCloud 복원 시 재가입 프로세스 유도 등 배포 요건 및 전체 품질 검증 | F77: =VLOOKUP(D77,CSR!$D$4:$E$1180,2,FALSE) -> CSR_11412 | G77: 3월 26일 | H77: 4 | I77: =H77*10/190 -> 0.21052632 | J77: QA1
A78: 4월 | B78: 기능 고도화 | C78: PASS기능개발 | D78: ㄴ26년 4월 앱 배포 검수 | E78: 4월 배포 건 CVT 1차 검증 - 품질팀 공유 항목 정리, 검증 환경 설정 지원, 검증 서버 앱 모니터링 등 대응 | F78: =VLOOKUP(D78,CSR!$D$4:$E$1180,2,FALSE) -> CSR_11412 | G78: 4월 4일 | H78: 4 | I78: =H78*10/190 -> 0.21052632 | J78: QA1
A79: 4월 | B79: 기능 고도화 | C79: PASS기능개발 | D79: ㄴ26년 4월 앱 배포 검수 | E79: 4월 배포 건 CVT 2차 검증 - 품질팀 공유 항목 정리, 검증 환경 설정 지원, 상용 서버 앱 모니터링 등 대응 | F79: =VLOOKUP(D79,CSR!$D$4:$E$1180,2,FALSE) -> CSR_11412 | G79: 4월 9일 | H79: 3 | I79: =H79*10/190 -> 0.15789474 | J79: QA1
A80: 4월 | B80: 기능 고도화 | C80: PASS기능개발 | D80: ㄴ26년 4월 앱 배포 검수 | E80: 스토어 4월 앱 배포 모니터링 - 배포 버전 확인 및 앱 모니터링 | F80: =VLOOKUP(D80,CSR!$D$4:$E$1180,2,FALSE) -> CSR_11412 | G80: 4월 13일 | H80: 1 | I80: =H80*10/190 -> 0.052631579 | J80: QA1
A81: 4월 | B81: 기능 고도화 | C81: PASS기능개발 | D81: 서비스 품질개선 | E81: 6월 배포 건 테스트 설계 - PASS 주소록 기능 고도화, PASS클라우드 추가 등 배포 요건 테스트 환경 설계 | F81: =VLOOKUP(D81,CSR!$D$4:$E$1180,2,FALSE) -> CSR_11400 | G81: 4월 15일 | H81: 4 | I81: =H81*10/190 -> 0.21052632 | J81: QA1
A82: 4월 | B82: 기능 고도화 | C82: PASS기능개발 | D82: 서비스 품질개선 | E82: 6월 배포 건 테스트 설계 - 오늘의게임 부가서비스, 외부플랫폼 브릿지 등 배포 요건 테스트 환경 설계 | F82: =VLOOKUP(D82,CSR!$D$4:$E$1180,2,FALSE) -> CSR_11400 | G82: 46132 | H82: 3 | I82: =H82*10/190 -> 0.15789474 | J82: QA1
A83: 3월 | B83: 기능 고도화 | C83: PASS기능개발 | D83: ㄴ26년 4월 앱 배포 검수 | E83: 26년 4월 개편 앱 DVT 대응 - DVT 수행 | F83: =VLOOKUP(D83,CSR!$D$4:$E$1180,2,FALSE) -> CSR_11412 | G83: 3월 26일 | H83: 4 | I83: =H83*10/190 -> 0.21052632 | J83: QA2
A84: 4월 | B84: 기능 고도화 | C84: PASS기능개발 | D84: ㄴ26년 4월 앱 배포 검수 | E84: 26년 4월 개편 앱 CVT 1차 대응 - CVT 1차 검증 | F84: =VLOOKUP(D84,CSR!$D$4:$E$1180,2,FALSE) -> CSR_11412 | G84: 4월 3일 | H84: 4 | I84: =H84*10/190 -> 0.21052632 | J84: QA2
A85: 4월 | B85: 기능 고도화 | C85: PASS기능개발 | D85: ㄴ26년 4월 앱 배포 검수 | E85: 26년 4월 개편 앱 CVT 2차 대응 - CVT 2차 검증 | F85: =VLOOKUP(D85,CSR!$D$4:$E$1180,2,FALSE) -> CSR_11412 | G85: 4월 9일 | H85: 3 | I85: =H85*10/190 -> 0.15789474 | J85: QA2
A86: 4월 | B86: 기능 고도화 | C86: PASS기능개발 | D86: ㄴ26년 4월 앱 배포 검수 | E86: 26년 4월 개편 앱 모니터링 대응 - 스토어 배포 및 모니터링 | F86: =VLOOKUP(D86,CSR!$D$4:$E$1180,2,FALSE) -> CSR_11412 | G86: 4월 13일 | H86: 1 | I86: =H86*10/190 -> 0.052631579 | J86: QA2
A87: 4월 | B87: 기능 고도화 | C87: PASS기능개발 | D87: 서비스 품질개선 | E87: 26년 6월 개편 앱 테스트 설계 - 6월 개편 앱 설계 | F87: =VLOOKUP(D87,CSR!$D$4:$E$1180,2,FALSE) -> CSR_11400 | G87: 4월 15일 | H87: 4 | I87: 0.21052632 | J87: QA2
A88: 4월 | B88: 기능 고도화 | C88: PASS기능개발 | D88: 서비스 품질개선 | E88: 26년 6월 개편 앱 테스트 설계 - 6월 개편 앱 설계 | F88: =VLOOKUP(D88,CSR!$D$4:$E$1180,2,FALSE) -> CSR_11400 | G88: 46132 | H88: 3 | I88: 0.15789474 | J88: QA2
A89: 3월 | B89: 서비스 품질관리 | C89: 서비스 운영 | D89: 업무보고 및 협의 | E89: PASS전략파트너 개발 관련 업무보고 및 협의 - 내부/외부 회의 및 협의 | F89: =VLOOKUP(D89,CSR!$D$4:$E$1180,2,FALSE) -> CSR_30600 | G89: 46108 | H89: 5 | I89: =H89*10/190 -> 0.26315789 | J89: 개발PM
A90: 4월 | B90: 서비스 품질관리 | C90: 서비스 운영 | D90: 업무보고 및 협의 | E90: PASS전략파트너 개발 관련 업무보고 및 협의 - 내부/외부 회의 및 협의 | F90: =VLOOKUP(D90,CSR!$D$4:$E$1180,2,FALSE) -> CSR_30600 | G90: 46115 | H90: 5 | I90: =H90*10/190 -> 0.26315789 | J90: 개발PM
A91: 4월 | B91: 서비스 품질관리 | C91: 서비스 운영 | D91: 업무보고 및 협의 | E91: PASS전략파트너 개발 관련 업무보고 및 협의 - 내부/외부 회의 및 협의 | F91: =VLOOKUP(D91,CSR!$D$4:$E$1180,2,FALSE) -> CSR_30600 | G91: 46122 | H91: 5 | I91: =H91*10/190 -> 0.26315789 | J91: 개발PM
A92: 4월 | B92: 서비스 품질관리 | C92: 서비스 운영 | D92: 업무보고 및 협의 | E92: PASS전략파트너 개발 관련 업무보고 및 협의 - 내부/외부 회의 및 협의 | F92: =VLOOKUP(D92,CSR!$D$4:$E$1180,2,FALSE) -> CSR_30600 | G92: 46132 | H92: 4 | I92: =H92*10/190 -> 0.21052632 | J92: 개발PM
A93: 3월 | B93: 서비스 품질관리 | C93: 서비스 운영 | D93: 업무보고 및 협의 | E93: PASS전략파트너 개발 관련 업무보고 및 협의 - 내부/외부 회의 및 협의 | F93: =VLOOKUP(D93,CSR!$D$4:$E$1180,2,FALSE) -> CSR_30600 | G93: 46108 | H93: 3 | I93: =H93*10/190 -> 0.15789474 | J93: 기획PM
A94: 4월 | B94: 서비스 품질관리 | C94: 서비스 운영 | D94: 업무보고 및 협의 | E94: PASS전략파트너 개발 관련 업무보고 및 협의 - 내부/외부 회의 및 협의 | F94: =VLOOKUP(D94,CSR!$D$4:$E$1180,2,FALSE) -> CSR_30600 | G94: 46115 | H94: 3 | I94: =H94*10/190 -> 0.15789474 | J94: 기획PM
A95: 4월 | B95: 신규사업 개발 | C95: 신규서비스 개발 | D95: ㄴ스마트청구서 개발 | E95: 스마트청구서 기획 1차안 작성 및 공유 | F95: =VLOOKUP(D95,CSR!$D$4:$E$1180,2,FALSE) -> CSR_41201 | G95: 4월 7일 | H95: 3 | I95: =H95*10/190 -> 0.15789474 | J95: 기획PM
A96: 4월 | B96: 서비스 품질관리 | C96: 서비스 운영 | D96: 업무보고 및 협의 | E96: PASS U+ 월례회의 : 개발항목 협의 | F96: =VLOOKUP(D96,CSR!$D$4:$E$1180,2,FALSE) -> CSR_30600 | G96: 4월 8일 | H96: 3 | I96: =H96*10/190 -> 0.15789474 | J96: 기획PM
A97: 4월 | B97: 서비스 품질관리 | C97: 서비스 운영 | D97: 업무보고 및 협의 | E97: PASS전략파트너 개발 관련 업무보고 및 협의 - 내부/외부 회의 및 협의 | F97: =VLOOKUP(D97,CSR!$D$4:$E$1180,2,FALSE) -> CSR_30600 | G97: 46122 | H97: 3 | I97: =H97*10/190 -> 0.15789474 | J97: 기획PM
A98: 4월 | B98: 서비스 품질관리 | C98: 서비스 운영 | D98: 업무보고 및 협의 | E98: PASS전략파트너 개발 관련 업무보고 및 협의 - 내부/외부 회의 및 협의 | F98: =VLOOKUP(D98,CSR!$D$4:$E$1180,2,FALSE) -> CSR_30600 | G98: 46129 | H98: 3 | I98: =H98*10/190 -> 0.15789474 | J98: 기획PM
A99: 4월 | B99: 기능고도화 | C99: PASS기능개발 | D99: PASS UI/UX 개선 | E99: PASS UI/UX 협의를 위한 리스트 작성 | F99: =VLOOKUP(D99,CSR!$D$4:$E$1180,2,FALSE) -> CSR_11500 | G99: 4월 17일 | H99: 1 | I99: =H99*10/190 -> 0.052631579 | J99: 기획PM
...

Sheet 26년03월
A1: 월 | B1: 구분 | C1: 중점추진과제 | D1: 상세추진과제 | E1: 상세 추진 내용 | F1: CSR ID | G1: 완료일시 | H1: 투입M/D | I1: 투입M/M | J1: 처리자 | K1: 비고
A2: 2월 | B2: 기능 고도화 | C2: PASS기능개발 | D2: ㄴ26년 3월 앱 배포 검수 | E2: 3월 배포 DVT 이슈 대응 및 소스 점검 - 주소록 | F2: =VLOOKUP(D2,[3]CSR!$D$4:$E$1159,2,FALSE) -> CSR_11409 | G2: 46080 | H2: 4 | I2: =H2*10/190 -> 0.21052632 | J2: Android개발자1
A3: 3월 | B3: 기능 고도화 | C3: PASS기능개발 | D3: 서비스 개발 | E3: 기존 문제점 수정 개발 및 DVT 앱 반영 - AOS | F3: =VLOOKUP(D3,[3]CSR!$D$4:$E$1159,2,FALSE) -> CSR_11300 | G3: 46087 | H3: 3 | I3: =H3*10/190 -> 0.15789474 | J3: Android개발자1
A4: 3월 | B4: 기능 고도화 | C4: PASS기능개발 | D4: ㄴ26년 3월 앱 배포 검수 | E4: 3월 배포 CVT 1차 앱 소스 머지 및 취합 점검 - AOS | F4: =VLOOKUP(D4,[3]CSR!$D$4:$E$1159,2,FALSE) -> CSR_11409 | G4: 46087 | H4: 2 | I4: =H4*10/190 -> 0.10526316 | J4: Android개발자1
A5: 3월 | B5: 기능 고도화 | C5: PASS기능개발 | D5: ㄴ26년 3월 앱 배포 검수 | E5: 앱 CVT 2차 앱 소스 머지 및 취합 점검 - AOS | F5: =VLOOKUP(D5,[3]CSR!$D$4:$E$1159,2,FALSE) -> CSR_11409 | G5: 46094 | H5: 2 | I5: =H5*10/190 -> 0.10526316 | J5: Android개발자1
A6: 3월 | B6: 기능 고도화 | C6: PASS기능개발 | D6: ㄴ PASS 전자고지 열람 시 IMEI 조회 실패 오류 안내 개선 | E6: 모바일지갑 IMEI 제거 개발 검토 - AOS | F6: =VLOOKUP(D6,[3]CSR!$D$4:$E$1159,2,FALSE) -> CSR_11312 | G6: 46094 | H6: 3 | I6: =H6*10/190 -> 0.15789474 | J6: Android개발자1
A7: 3월 | B7: 기능 고도화 | C7: PASS기능개발 | D7: ㄴ26년 3월 앱 배포 검수 | E7: 스토어 앱 배포 및 이슈 점검 - AOS | F7: =VLOOKUP(D7,[3]CSR!$D$4:$E$1159,2,FALSE) -> CSR_11409 | G7: 46101 | H7: 1 | I7: =H7*10/190 -> 0.052631579 | J7: Android개발자1
A8: 3월 | B8: 기능 고도화 | C8: PASS기능개발 | D8: 서비스 개발 | E8: MIS SDK 업데이트 개발 - AOS | F8: =VLOOKUP(D8,[3]CSR!$D$4:$E$1159,2,FALSE) -> CSR_11300 | G8: 46101 | H8: 2 | I8: =H8*10/190 -> 0.10526316 | J8: Android개발자1
A9: 3월 | B9: 신규사업 개발 | C9: 신규서비스개발 | D9: ㄴPASS클라우드 | E9: 신규부가서비스 PASS 클라우드 추가 건 내부 개발 검토 - AOS | F9: =VLOOKUP(D9,[3]CSR!$D$4:$E$1159,2,FALSE) -> CSR_41103 | G9: 46101 | H9: 2 | I9: =H9*10/190 -> 0.10526316 | J9: Android개발자1
A10: 2월 | B10: 기능 고도화 | C10: PASS기능개발 | D10: PASS 앱인앱 고도화 (웹뷰 고도화) | E10: 인앱브라우처 웹타입 추가 건 기획 초안 검토 및 협의 - AOS | F10: =VLOOKUP(D10,[3]CSR!$D$4:$E$1159,2,FALSE) -> CSR_10700 | G10: 46080 | H10: 3 | I10: =H10*10/190 -> 0.15789474 | J10: Android개발자2
A11: 2월 | B11: 기능 고도화 | C11: PASS기능개발 | D11: ㄴ26년 3월 앱 배포 검수 | E11: 3월 배포 DVT 이슈 대응 및 소스 점검 - PASS 머니 회원 탈퇴 | F11: =VLOOKUP(D11,[3]CSR!$D$4:$E$1159,2,FALSE) -> CSR_11409 | G11: 46080 | H11: 2 | I11: =H11*10/190 -> 0.10526316 | J11: Android개발자2
A12: 3월 | B12: 기능 고도화 | C12: PASS기능개발 | D12: ㄴ26년 3월 앱 배포 검수 | E12: 3월 배포 DVT 이슈 대응 및 소스 점검 - 고객의소리 URL 변경 | F12: =VLOOKUP(D12,[3]CSR!$D$4:$E$1159,2,FALSE) -> CSR_11409 | G12: 46087 | H12: 2 | I12: =H12*10/190 -> 0.10526316 | J12: Android개발자2
A13: 3월 | B13: 기능 고도화 | C13: PASS기능개발 | D13: ㄴ26년 3월 앱 배포 검수 | E13: 앱 CVT 1차 대응 및 내부 점검 - AOS | F13: =VLOOKUP(D13,[3]CSR!$D$4:$E$1159,2,FALSE) -> CSR_11409 | G13: 46087 | H13: 1 | I13: =H13*10/190 -> 0.052631579 | J13: Android개발자2
... A88: 2월 | B88: 기능 고도화 | C88: PASS기능개발 | D88: ㄴ26년 3월 앱 배포 검수 | E88: 26년 3월 정기 배포 검수 - DVT(검수 환경) 수행 | F88: =VLOOKUP(D88,[3]CSR!$D$4:$E$1159,2,FALSE) -> CSR_11409 | G88: 46080 | H88: 1 | I88: =H88*10/190 -> 0.052631579 | J88: QA1
A89: 3월 | B89: 기능 고도화 | C89: PASS기능개발 | D89: ㄴ26년 3월 앱 배포 검수 | E89: 26년 3월 정기 배포 검수 - CVT 1차(검수 환경) 대응 - 검수 앱 점검 | F89: =VLOOKUP(D89,[3]CSR!$D$4:$E$1159,2,FALSE) -> CSR_11409 | G89: 3월 10일 | H89: 3 | I89: =H89*10/190 -> 0.15789474 | J89: QA1
A90: 3월 | B90: 기능 고도화 | C90: PASS기능개발 | D90: ㄴ26년 3월 앱 배포 검수 | E90: 26년 3월 정기 배포 검수 - CVT 2차(상용 환경) 대응 - 상용 앱 점검 | F90: =VLOOKUP(D90,[3]CSR!$D$4:$E$1159,2,FALSE) -> CSR_11409 | G90: 3월 13일 | H90: 1 | I90: =H90*10/190 -> 0.052631579 | J90: QA1
A91: 3월 | B91: 기능 고도화 | C91: PASS기능개발 | D91: ㄴ26년 3월 2차 서버 검수 | E91: 26년 3월 정기 배포 검수 - 모바일신분증 기능 검증 - 부가서비스 기능 검증 | F91: =VLOOKUP(D91,[3]CSR!$D$4:$E$1159,2,FALSE) -> CSR_11411 | G91: 3월 16일 | H91: 1 | I91: =H91*10/190 -> 0.052631579 | J91: QA1
A92: 3월 | B92: 기능 고도화 | C92: PASS기능개발 | D92: ㄴ26년 3월 앱 배포 검수 | E92: 26년 3월 정기 배포 검수 - 스토어 배포 대응 | F92: =VLOOKUP(D92,[3]CSR!$D$4:$E$1159,2,FALSE) -> CSR_11409 | G92: 3월 18일 | H92: 2 | I92: =H92*10/190 -> 0.10526316 | J92: QA1
A93: 3월 | B93: 기능 고도화 | C93: PASS기능개발 | D93: ㄴ26년 3월 앱 배포 검수 | E93: 26년 3월 정기 배포 검수 - 스토어 배포 대응 | F93: CSR_11409 | G93: 3월 18일 | H93: 2 | I93: =H93*10/190 -> 0.10526316 | J93: QA1
A94: 3월 | B94: 기능 고도화 | C94: PASS기능개발 | D94: 서비스 개발 | E94: 기존 문제점 내부 검토 - iCloud 복원 시 재가입 프로세스 진행 현황 검토 | F94: =VLOOKUP(D94,[3]CSR!$D$4:$E$1159,2,FALSE) -> CSR_11300 | G94: 3월 20일 | H94: 1 | I94: =H94*10/190 -> 0.052631579 | J94: QA1
A95: 3월 | B95: 기능 고도화 | C95: PASS기능개발 | D95: 서비스 개발 | E95: 기존 문제점 내부 검토 - iCloud 복원 시 재가입 프로세스 진행 현황 검토 | F95: CSR_11300 | G95: 3월 20일 | H95: 2 | I95: =H95*10/190 -> 0.10526316 | J95: QA1
A96: 3월 | B96: 기능 고도화 | C96: PASS기능개발 | D96: ㄴ26년 3월 앱 배포 검수 | E96: 26년 3월 정기 배포 검수 - DVT(검수 환경) 수행 | F96: =VLOOKUP(D96,[3]CSR!$D$4:$E$1159,2,FALSE) -> CSR_11409 | G96: 3월 5일 | H96: 3 | I96: =H96*10/190 -> 0.15789474 | J96: QA1
A97: 2월 | B97: 기능 고도화 | C97: PASS기능개발 | D97: ㄴ26년 3월 앱 배포 검수 | E97: 26년 3월 배포 앱 DVT - DVT 수행 | F97: CSR_11409 | G97: 2월 26일 | H97: 4 | I97: =H97*10/190 -> 0.21052632 | J97: QA2
A98: 2월 | B98: 기능 고도화 | C98: PASS기능개발 | D98: ㄴ26년 3월 앱 배포 검수 | E98: 26년 3월 배포 앱 DVT - DVT 수행 | F98: CSR_11409 | G98: 2월 27일 | H98: 2 | I98: =H98*10/190 -> 0.10526316 | J98: QA2
A99: 3월 | B99: 기능 고도화 | C99: PASS기능개발 | D99: ㄴ26년 3월 앱 배포 검수 | E99: 26년 3월 개편 앱 CVT 1차 대응 - CVT 1차 이슈 항목 점검 - 검수 앱 점검 | F99: CSR_11409 | G99: 3월 11일 | H99: 4 | I99: =H99*10/190 -> 0.21052632 | J99: QA2
A100: 3월 | B100: 기능 고도화 | C100: PASS기능개발 | D100: ㄴ26년 3월 앱 배포 검수 | E100: 26년 3월 개편 앱 CVT 2차 대응 - CVT 2차 사용앱 점검 | F100: CSR_11409 | G100: 3월 13일 | H100: 2 | I100: =H100*10/190 -> 0.10526316 | J100: QA2
A101: 3월 | B101: 기능 고도화 | C101: PASS기능개발 | D101: ㄴ26년 3월 2차 서버 검수 | E101: 26년 3월 정기 배포 검수 - 모바일신분증 기능 검증 - 부가서비스 기능 검증 | F101: CSR_11411 | G101: 3월 16일 | H101: 1 | I101: =H101*10/190 -> 0.052631579 | J101: QA2
A102: 3월 | B102: 기능 고도화 | C102: PASS기능개발 | D102: ㄴ26년 3월 앱 배포 검수 | E102: 26년 3월 배포 앱 DVT - DVT 수행 | F102: CSR_11409 | G102: 3월 4일 | H102: 2 | I102: =H102*10/190 -> 0.10526316 | J102: QA2
A103: 3월 | B103: 기능 고도화 | C103: PASS기능개발 | D103: ㄴ26년 3월 앱 배포 검수 | E103: 26년 3월 개편 앱 CVT 1차 대응 - CVT 1차 이슈 항목 점검 - 검수 앱 점검 | F103: CSR_11409 | G103: 3월 6일 | H103: 4 | I103: =H103*10/190 -> 0.21052632 | J103: QA2
A104: 2월 | B104: 서비스 품질관리 | C104: 서비스 운영 | D104: 업무보고 및 협의 | E104: PASS전략파트너 개발 관련 업무보고 및 협의 - 내부/외부 회의 및 협의 | F104: =VLOOKUP(D104,[3]CSR!$D$4:$E$1159,2,FALSE) -> CSR_30600 | G104: 46080 | H104: 5 | I104: =H104*10/190 -> 0.26315789 | J104: 개발PM
A105: 3월 | B105: 서비스 품질관리 | C105: 서비스 운영 | D105: 업무보고 및 협의 | E105: PASS전략파트너 개발 관련 업무보고 및 협의 - 내부/외부 회의 및 협의 | F105: =VLOOKUP(D105,[3]CSR!$D$4:$E$1159,2,FALSE) -> CSR_30600 | G105: 46087 | H105: 5 | I105: =H105*10/190 -> 0.26315789 | J105: 개발PM
A106: 3월 | B106: 서비스 품질관리 | C106: 서비스 운영 | D106: 업무보고 및 협의 | E106: PASS전략파트너 개발 관련 업무보고 및 협의 - 내부/외부 회의 및 협의 | F106: =VLOOKUP(D106,[3]CSR!$D$4:$E$1159,2,FALSE) -> CSR_30600 | G106: 46094 | H106: 5 | I106: =H106*10/190 -> 0.26315789 | J106: 개발PM
A107: 3월 | B107: 서비스 품질관리 | C107: 서비스 운영 | D107: 업무보고 및 협의 | E107: PASS전략파트너 개발 관련 업무보고 및 협의 - 내부/외부 회의 및 협의 | F107: =VLOOKUP(D107,[3]CSR!$D$4:$E$1159,2,FALSE) -> CSR_30600 | G107: 46101 | H107: 4 | I107: =H107*10/190 -> 0.21052632 | J107: 개발PM
A108: 3월 | B108: 서비스 품질관리 | C108: 서비스 운영 | D108: 업무보고 및 협의 | E108: PASS전략파트너 개발 관련 업무보고 및 협의 - 내부/외부 회의 및 협의 | F108: CSR_30600 | G108: 46080 | H108: 5 | I108: =H108*10/190 -> 0.26315789 | J108: 기획PM
A109: 3월 | B109: 서비스 품질관리 | C109: 서비스 운영 | D109: 업무보고 및 협의 | E109: PASS전략파트너 개발 관련 업무보고 및 협의 - 내부/외부 회의 및 협의 | F109: CSR_30600 | G109: 46087 | H109: 4 | I109: =H109*10/190 -> 0.21052632 | J109: 기획PM
A110: 3월 | B110: 서비스 품질관리 | C110: 서비스 운영 | D110: 업무보고 및 협의 | E110: PASS전략파트너 개발 관련 업무보고 및 협의 - 내부/외부 회의 및 협의 | F110: CSR_30600 | G110: 46094 | H110: 5 | I110: =H110*10/190 -> 0.26315789 | J110: 기획PM
A111: 3월 | B111: 서비스 품질관리 | C111: 서비스 운영 | D111: 업무보고 및 협의 | E111: PASS전략파트너 개발 관련 업무보고 및 협의 - 내부/외부 회의 및 협의 | F111: CSR_30600 | G111: 46101 | H111: 5 | I111: =H111*10/190 -> 0.26315789 | J111: 기획PM
A112: 3월 | B112: 신규사업 개발 | C112: 인증플랫폼 | D112: 통신업무 "안면인증" PASS 활용 기능 및 사업화 | E112: 안면인증 통계 고도화 - 데이터 추출기준 변경 및 기획서 수정 | F112: =VLOOKUP(D112,[4]CSR!$D$4:$E$1151,2,FALSE) -> CSR_40400 | G112: 46092 | H112: 2 | I112: =H112*10/190 -> 0.10526316 | J112: 기획자1
A113: 3월 | B113: 서비스 품질관리 | C113: 서비스 운영 | D113: VOC 처리, 대응 및 사용자 공지 | E113: 1. 모바일운전면허 확인서비스 장애 대응 (2/27~3/1) 2. 모바일운전면허 확인서비스 공지등록요청 (3회) 3. PASS전자고지 열람 오류 VOC - 개발팀 검토 요청 및 개선 방향 협의 | F113: =VLOOKUP(D113,[4]CSR!$D$4:$E$1151,2,FALSE) -> CSR_30300 | G113: 46098 | H113: 1 | I113: =H113*10/190 -> 0.052631579 | J113: 기획자1
A114: 3월 | B114: 신규사업 개발 | C114: 인증플랫폼 | D114: 모바일신분증 고도화 (라인업 확대_시민증 관광증) | E114: 모바일신분증 제3자제공 이용기관 리스트 - 가맹점 데이터 현행화 요청 및 웹뷰 제작 요청 | F114: =VLOOKUP(D114,[4]CSR!$D$4:$E$1151,2,FALSE) -> CSR_40300 | G114: 46099 | H114: 1 | I114: =H114*10/190 -> 0.052631579 | J114: 기획자1
...

Sheet 26년02월
A1: 월 | B1: 구분 | C1: 중점추진과제 | D1: 상세추진과제 | E1: 상세 추진 내용 | F1: CSR ID | G1: 완료일시 | H1: 투입M/D | I1: 투입M/M | J1: 처리자 | K1: 비고
